fill ~0 ~0 ~0 ~9 ~0 ~0 minecraft:smooth_stone
fill ~0 ~0 ~1 ~9 ~0 ~1 minecraft:smooth_stone
fill ~0 ~0 ~2 ~9 ~0 ~2 minecraft:smooth_stone
fill ~0 ~0 ~3 ~9 ~0 ~3 minecraft:smooth_stone
fill ~0 ~0 ~4 ~9 ~0 ~4 minecraft:smooth_stone
fill ~0 ~0 ~5 ~9 ~0 ~5 minecraft:smooth_stone
setblock ~2 ~1 ~1 minecraft:sticky_piston[facing=east]
setblock ~3 ~1 ~1 minecraft:stone_bricks
setblock ~6 ~1 ~1 minecraft:stone_bricks
setblock ~7 ~1 ~1 minecraft:sticky_piston[facing=west]
setblock ~2 ~1 ~2 minecraft:smooth_stone
setblock ~7 ~1 ~2 minecraft:smooth_stone
setblock ~2 ~1 ~3 minecraft:smooth_stone
setblock ~7 ~1 ~3 minecraft:smooth_stone
fill ~0 ~1 ~4 ~9 ~1 ~4 minecraft:smooth_stone
setblock ~5 ~1 ~5 minecraft:smooth_stone
setblock ~2 ~2 ~1 minecraft:sticky_piston[facing=east]
setblock ~3 ~2 ~1 minecraft:stone_bricks
setblock ~6 ~2 ~1 minecraft:stone_bricks
setblock ~7 ~2 ~1 minecraft:sticky_piston[facing=west]
setblock ~2 ~2 ~2 minecraft:smooth_stone
setblock ~7 ~2 ~2 minecraft:smooth_stone
fill ~2 ~3 ~1 ~7 ~3 ~1 minecraft:smooth_stone
setblock ~0 ~1 ~2 minecraft:redstone_wire
setblock ~1 ~1 ~2 minecraft:redstone_wire
setblock ~8 ~1 ~2 minecraft:redstone_wire
setblock ~9 ~1 ~2 minecraft:redstone_wire
setblock ~0 ~1 ~3 minecraft:redstone_wire
setblock ~9 ~1 ~3 minecraft:redstone_wire
setblock ~2 ~2 ~3 minecraft:redstone_wire
setblock ~7 ~2 ~3 minecraft:redstone_wire
setblock ~0 ~2 ~4 minecraft:redstone_wire
setblock ~1 ~2 ~4 minecraft:redstone_wire
setblock ~2 ~2 ~4 minecraft:redstone_wire
setblock ~3 ~2 ~4 minecraft:redstone_wire
setblock ~4 ~2 ~4 minecraft:redstone_wire
setblock ~5 ~2 ~4 minecraft:redstone_wire
setblock ~6 ~2 ~4 minecraft:redstone_wire
setblock ~7 ~2 ~4 minecraft:redstone_wire
setblock ~8 ~2 ~4 minecraft:redstone_wire
setblock ~9 ~2 ~4 minecraft:redstone_wire
setblock ~5 ~2 ~5 minecraft:lever[face=floor,facing=north,powered=false]
