setblock ~0 ~0 ~0 minecraft:stone_bricks
setblock ~1 ~0 ~0 minecraft:polished_andesite
setblock ~2 ~0 ~0 minecraft:stone_bricks
setblock ~3 ~0 ~0 minecraft:polished_andesite
setblock ~4 ~0 ~0 minecraft:stone_bricks
setblock ~5 ~0 ~0 minecraft:polished_andesite
setblock ~6 ~0 ~0 minecraft:stone_bricks
setblock ~7 ~0 ~0 minecraft:polished_andesite
setblock ~8 ~0 ~0 minecraft:stone_bricks
setblock ~9 ~0 ~0 minecraft:polished_andesite
setblock ~10 ~0 ~0 minecraft:stone_bricks
setblock ~11 ~0 ~0 minecraft:polished_andesite
setblock ~12 ~0 ~0 minecraft:stone_bricks
setblock ~13 ~0 ~0 minecraft:polished_andesite
setblock ~14 ~0 ~0 minecraft:stone_bricks
setblock ~15 ~0 ~0 minecraft:polished_andesite
setblock ~0 ~0 ~1 minecraft:polished_andesite
setblock ~1 ~0 ~1 minecraft:stone_bricks
setblock ~2 ~0 ~1 minecraft:polished_andesite
setblock ~3 ~0 ~1 minecraft:stone_bricks
setblock ~4 ~0 ~1 minecraft:polished_andesite
setblock ~5 ~0 ~1 minecraft:obsidian
setblock ~6 ~0 ~1 minecraft:crying_obsidian
setblock ~7 ~0 ~1 minecraft:obsidian
setblock ~8 ~0 ~1 minecraft:crying_obsidian
setblock ~9 ~0 ~1 minecraft:obsidian
setblock ~10 ~0 ~1 minecraft:crying_obsidian
setblock ~11 ~0 ~1 minecraft:obsidian
setblock ~12 ~0 ~1 minecraft:crying_obsidian
setblock ~13 ~0 ~1 minecraft:stone_bricks
setblock ~14 ~0 ~1 minecraft:polished_andesite
setblock ~15 ~0 ~1 minecraft:stone_bricks
setblock ~0 ~0 ~2 minecraft:stone_bricks
setblock ~1 ~0 ~2 minecraft:polished_andesite
setblock ~2 ~0 ~2 minecraft:stone_bricks
setblock ~3 ~0 ~2 minecraft:polished_andesite
setblock ~4 ~0 ~2 minecraft:stone_bricks
setblock ~5 ~0 ~2 minecraft:polished_andesite
setblock ~6 ~0 ~2 minecraft:stone_bricks
setblock ~7 ~0 ~2 minecraft:polished_andesite
setblock ~8 ~0 ~2 minecraft:stone_bricks
setblock ~9 ~0 ~2 minecraft:polished_andesite
setblock ~10 ~0 ~2 minecraft:stone_bricks
setblock ~11 ~0 ~2 minecraft:polished_andesite
setblock ~12 ~0 ~2 minecraft:stone_bricks
setblock ~13 ~0 ~2 minecraft:polished_andesite
setblock ~14 ~0 ~2 minecraft:stone_bricks
setblock ~15 ~0 ~2 minecraft:polished_andesite
setblock ~0 ~0 ~3 minecraft:polished_andesite
setblock ~1 ~0 ~3 minecraft:stone_bricks
setblock ~2 ~0 ~3 minecraft:polished_andesite
setblock ~3 ~0 ~3 minecraft:stone_bricks
setblock ~4 ~0 ~3 minecraft:polished_andesite
setblock ~5 ~0 ~3 minecraft:stone_bricks
setblock ~6 ~0 ~3 minecraft:polished_andesite
setblock ~7 ~0 ~3 minecraft:stone_bricks
setblock ~8 ~0 ~3 minecraft:polished_andesite
setblock ~9 ~0 ~3 minecraft:stone_bricks
setblock ~10 ~0 ~3 minecraft:polished_andesite
setblock ~11 ~0 ~3 minecraft:stone_bricks
setblock ~12 ~0 ~3 minecraft:polished_andesite
setblock ~13 ~0 ~3 minecraft:stone_bricks
setblock ~14 ~0 ~3 minecraft:polished_andesite
setblock ~15 ~0 ~3 minecraft:stone_bricks
setblock ~0 ~0 ~4 minecraft:stone_bricks
setblock ~1 ~0 ~4 minecraft:polished_andesite
setblock ~2 ~0 ~4 minecraft:stone_bricks
setblock ~3 ~0 ~4 minecraft:polished_andesite
setblock ~4 ~0 ~4 minecraft:stone_bricks
setblock ~5 ~0 ~4 minecraft:polished_andesite
setblock ~6 ~0 ~4 minecraft:stone_bricks
setblock ~7 ~0 ~4 minecraft:polished_andesite
setblock ~8 ~0 ~4 minecraft:stone_bricks
setblock ~9 ~0 ~4 minecraft:polished_andesite
setblock ~10 ~0 ~4 minecraft:stone_bricks
setblock ~11 ~0 ~4 minecraft:polished_andesite
setblock ~12 ~0 ~4 minecraft:stone_bricks
setblock ~13 ~0 ~4 minecraft:polished_andesite
setblock ~14 ~0 ~4 minecraft:stone_bricks
setblock ~15 ~0 ~4 minecraft:polished_andesite
setblock ~0 ~0 ~5 minecraft:polished_andesite
setblock ~1 ~0 ~5 minecraft:stone_bricks
setblock ~2 ~0 ~5 minecraft:polished_andesite
setblock ~3 ~0 ~5 minecraft:stone_bricks
setblock ~4 ~0 ~5 minecraft:polished_andesite
setblock ~5 ~0 ~5 minecraft:stone_bricks
setblock ~6 ~0 ~5 minecraft:polished_andesite
setblock ~7 ~0 ~5 minecraft:stone_bricks
setblock ~8 ~0 ~5 minecraft:polished_andesite
setblock ~9 ~0 ~5 minecraft:stone_bricks
setblock ~10 ~0 ~5 minecraft:polished_andesite
setblock ~11 ~0 ~5 minecraft:stone_bricks
setblock ~12 ~0 ~5 minecraft:polished_andesite
setblock ~13 ~0 ~5 minecraft:stone_bricks
setblock ~14 ~0 ~5 minecraft:polished_andesite
setblock ~15 ~0 ~5 minecraft:stone_bricks
fill ~0 ~1 ~1 ~4 ~1 ~1 minecraft:stone_bricks
setblock ~5 ~1 ~1 minecraft:crying_obsidian
fill ~6 ~1 ~1 ~7 ~1 ~1 minecraft:slime_block
setblock ~11 ~1 ~1 minecraft:honey_block
setblock ~12 ~1 ~1 minecraft:crying_obsidian
fill ~13 ~1 ~1 ~15 ~1 ~1 minecraft:stone_bricks
fill ~0 ~2 ~1 ~3 ~2 ~1 minecraft:stone_bricks
setblock ~5 ~2 ~1 minecraft:sticky_piston[facing=east]
fill ~6 ~2 ~1 ~7 ~2 ~1 minecraft:slime_block
setblock ~11 ~2 ~1 minecraft:honey_block
setblock ~12 ~2 ~1 minecraft:sticky_piston[facing=west]
setblock ~13 ~2 ~1 minecraft:smooth_stone
fill ~14 ~2 ~1 ~15 ~2 ~1 minecraft:stone_bricks
setblock ~13 ~2 ~2 minecraft:smooth_stone
fill ~0 ~3 ~1 ~4 ~3 ~1 minecraft:stone_bricks
setblock ~5 ~3 ~1 minecraft:crying_obsidian
fill ~6 ~3 ~1 ~7 ~3 ~1 minecraft:slime_block
setblock ~11 ~3 ~1 minecraft:honey_block
setblock ~12 ~3 ~1 minecraft:crying_obsidian
fill ~14 ~3 ~1 ~15 ~3 ~1 minecraft:stone_bricks
setblock ~13 ~3 ~3 minecraft:smooth_stone
fill ~0 ~4 ~1 ~4 ~4 ~1 minecraft:stone_bricks
setblock ~6 ~4 ~1 minecraft:sticky_piston[facing=east]
setblock ~7 ~4 ~1 minecraft:slime_block
fill ~10 ~4 ~1 ~11 ~4 ~1 minecraft:crying_obsidian
setblock ~13 ~4 ~1 minecraft:stone_bricks
setblock ~14 ~4 ~1 minecraft:smooth_stone
setblock ~15 ~4 ~1 minecraft:stone_bricks
fill ~1 ~4 ~2 ~5 ~4 ~2 minecraft:smooth_stone
setblock ~14 ~4 ~2 minecraft:smooth_stone
setblock ~1 ~4 ~3 minecraft:smooth_stone
setblock ~5 ~4 ~3 minecraft:smooth_stone
setblock ~14 ~4 ~3 minecraft:smooth_stone
setblock ~0 ~4 ~4 minecraft:stone_bricks
fill ~1 ~4 ~4 ~14 ~4 ~4 minecraft:smooth_stone
setblock ~15 ~4 ~4 minecraft:stone_bricks
fill ~1 ~4 ~5 ~14 ~4 ~5 minecraft:stone_bricks
fill ~0 ~5 ~1 ~4 ~5 ~1 minecraft:stone_bricks
fill ~6 ~5 ~1 ~7 ~5 ~1 minecraft:obsidian
setblock ~8 ~5 ~1 minecraft:crying_obsidian
setblock ~9 ~5 ~1 minecraft:obsidian
setblock ~10 ~5 ~1 minecraft:crying_obsidian
setblock ~11 ~5 ~1 minecraft:obsidian
fill ~12 ~5 ~1 ~13 ~5 ~1 minecraft:smooth_stone
setblock ~15 ~5 ~1 minecraft:stone_bricks
setblock ~0 ~5 ~4 minecraft:stone_bricks
setblock ~15 ~5 ~4 minecraft:stone_bricks
fill ~1 ~5 ~5 ~14 ~5 ~5 minecraft:stone_bricks
fill ~0 ~6 ~1 ~5 ~6 ~1 minecraft:stone_bricks
setblock ~15 ~6 ~1 minecraft:stone_bricks
fill ~1 ~6 ~2 ~5 ~6 ~2 minecraft:stone_bricks
setblock ~14 ~6 ~2 minecraft:stone_bricks
fill ~1 ~6 ~3 ~5 ~6 ~3 minecraft:stone_bricks
setblock ~14 ~6 ~3 minecraft:stone_bricks
fill ~0 ~6 ~4 ~15 ~6 ~4 minecraft:stone_bricks
fill ~1 ~6 ~5 ~14 ~6 ~5 minecraft:stone_bricks
fill ~0 ~7 ~1 ~15 ~7 ~1 minecraft:stone_bricks
setblock ~3 ~1 ~0 minecraft:lantern[hanging=false]
setblock ~15 ~1 ~0 minecraft:lantern[hanging=false]
setblock ~3 ~1 ~2 minecraft:lantern[hanging=false]
setblock ~15 ~1 ~3 minecraft:lantern[hanging=false]
setblock ~13 ~2 ~3 minecraft:lever[face=wall,facing=south,powered=false]
setblock ~13 ~3 ~1 minecraft:redstone_wire
setblock ~13 ~3 ~2 minecraft:redstone_wire
setblock ~5 ~4 ~1 minecraft:redstone_wire
setblock ~13 ~4 ~3 minecraft:redstone_wire
setblock ~14 ~5 ~1 minecraft:redstone_wire
setblock ~1 ~5 ~2 minecraft:redstone_wire
setblock ~2 ~5 ~2 minecraft:repeater[facing=west,delay=4]
setblock ~3 ~5 ~2 minecraft:repeater[facing=west,delay=4]
setblock ~4 ~5 ~2 minecraft:repeater[facing=west,delay=4]
setblock ~5 ~5 ~2 minecraft:redstone_wire
setblock ~14 ~5 ~2 minecraft:repeater[facing=south,delay=4]
setblock ~1 ~5 ~3 minecraft:redstone_wire
setblock ~5 ~5 ~3 minecraft:repeater[facing=south,delay=1]
setblock ~14 ~5 ~3 minecraft:repeater[facing=south,delay=4]
setblock ~1 ~5 ~4 minecraft:redstone_wire
setblock ~2 ~5 ~4 minecraft:redstone_wire
setblock ~3 ~5 ~4 minecraft:redstone_wire
setblock ~4 ~5 ~4 minecraft:redstone_wire
setblock ~5 ~5 ~4 minecraft:redstone_wire
setblock ~6 ~5 ~4 minecraft:redstone_wire
setblock ~7 ~5 ~4 minecraft:redstone_wire
setblock ~8 ~5 ~4 minecraft:redstone_wire
setblock ~9 ~5 ~4 minecraft:redstone_wire
setblock ~10 ~5 ~4 minecraft:repeater[facing=east,delay=1]
setblock ~11 ~5 ~4 minecraft:redstone_wire
setblock ~12 ~5 ~4 minecraft:redstone_wire
setblock ~13 ~5 ~4 minecraft:redstone_wire
setblock ~14 ~5 ~4 minecraft:redstone_wire
setblock ~6 ~6 ~1 minecraft:redstone_wire
setblock ~7 ~6 ~1 minecraft:redstone_wire
setblock ~8 ~6 ~1 minecraft:redstone_wire
setblock ~9 ~6 ~1 minecraft:redstone_wire
setblock ~10 ~6 ~1 minecraft:redstone_wire
setblock ~11 ~6 ~1 minecraft:redstone_wire
setblock ~12 ~6 ~1 minecraft:redstone_wire
setblock ~13 ~6 ~1 minecraft:redstone_wire
