fill ~0 ~0 ~0 ~15 ~0 ~0 minecraft:smooth_stone
fill ~0 ~0 ~1 ~4 ~0 ~1 minecraft:smooth_stone
fill ~5 ~0 ~1 ~12 ~0 ~1 minecraft:obsidian
fill ~13 ~0 ~1 ~15 ~0 ~1 minecraft:smooth_stone
fill ~0 ~0 ~2 ~15 ~0 ~2 minecraft:smooth_stone
fill ~0 ~0 ~3 ~15 ~0 ~3 minecraft:smooth_stone
fill ~0 ~0 ~4 ~15 ~0 ~4 minecraft:smooth_stone
fill ~0 ~0 ~5 ~15 ~0 ~5 minecraft:smooth_stone
setblock ~5 ~1 ~1 minecraft:obsidian
fill ~6 ~1 ~1 ~7 ~1 ~1 minecraft:slime_block
setblock ~11 ~1 ~1 minecraft:honey_block
setblock ~12 ~1 ~1 minecraft:obsidian
setblock ~5 ~2 ~1 minecraft:sticky_piston[facing=east]
fill ~6 ~2 ~1 ~7 ~2 ~1 minecraft:slime_block
setblock ~11 ~2 ~1 minecraft:honey_block
setblock ~12 ~2 ~1 minecraft:sticky_piston[facing=west]
setblock ~13 ~2 ~1 minecraft:smooth_stone
setblock ~13 ~2 ~2 minecraft:smooth_stone
setblock ~5 ~3 ~1 minecraft:obsidian
fill ~6 ~3 ~1 ~7 ~3 ~1 minecraft:slime_block
setblock ~11 ~3 ~1 minecraft:honey_block
setblock ~12 ~3 ~1 minecraft:obsidian
setblock ~13 ~3 ~3 minecraft:smooth_stone
setblock ~6 ~4 ~1 minecraft:sticky_piston[facing=east]
setblock ~7 ~4 ~1 minecraft:slime_block
fill ~10 ~4 ~1 ~11 ~4 ~1 minecraft:obsidian
setblock ~14 ~4 ~1 minecraft:smooth_stone
fill ~1 ~4 ~2 ~5 ~4 ~2 minecraft:smooth_stone
setblock ~14 ~4 ~2 minecraft:smooth_stone
setblock ~1 ~4 ~3 minecraft:smooth_stone
setblock ~5 ~4 ~3 minecraft:smooth_stone
setblock ~14 ~4 ~3 minecraft:smooth_stone
fill ~1 ~4 ~4 ~14 ~4 ~4 minecraft:smooth_stone
fill ~6 ~5 ~1 ~11 ~5 ~1 minecraft:obsidian
fill ~12 ~5 ~1 ~13 ~5 ~1 minecraft:smooth_stone
setblock ~13 ~2 ~3 minecraft:lever[face=wall,facing=south,powered=false]
setblock ~13 ~3 ~1 minecraft:redstone_wire
setblock ~13 ~3 ~2 minecraft:redstone_wire
setblock ~5 ~4 ~1 minecraft:redstone_wire
setblock ~13 ~4 ~3 minecraft:redstone_wire
setblock ~14 ~5 ~1 minecraft:redstone_wire
setblock ~1 ~5 ~2 minecraft:redstone_wire
setblock ~2 ~5 ~2 minecraft:repeater[facing=west,delay=4]
setblock ~3 ~5 ~2 minecraft:repeater[facing=west,delay=4]
setblock ~4 ~5 ~2 minecraft:repeater[facing=west,delay=4]
setblock ~5 ~5 ~2 minecraft:redstone_wire
setblock ~14 ~5 ~2 minecraft:repeater[facing=south,delay=4]
setblock ~1 ~5 ~3 minecraft:redstone_wire
setblock ~5 ~5 ~3 minecraft:repeater[facing=south,delay=1]
setblock ~14 ~5 ~3 minecraft:repeater[facing=south,delay=4]
setblock ~1 ~5 ~4 minecraft:redstone_wire
setblock ~2 ~5 ~4 minecraft:redstone_wire
setblock ~3 ~5 ~4 minecraft:redstone_wire
setblock ~4 ~5 ~4 minecraft:redstone_wire
setblock ~5 ~5 ~4 minecraft:redstone_wire
setblock ~6 ~5 ~4 minecraft:redstone_wire
setblock ~7 ~5 ~4 minecraft:redstone_wire
setblock ~8 ~5 ~4 minecraft:redstone_wire
setblock ~9 ~5 ~4 minecraft:redstone_wire
setblock ~10 ~5 ~4 minecraft:repeater[facing=east,delay=1]
setblock ~11 ~5 ~4 minecraft:redstone_wire
setblock ~12 ~5 ~4 minecraft:redstone_wire
setblock ~13 ~5 ~4 minecraft:redstone_wire
setblock ~14 ~5 ~4 minecraft:redstone_wire
setblock ~6 ~6 ~1 minecraft:redstone_wire
setblock ~7 ~6 ~1 minecraft:redstone_wire
setblock ~8 ~6 ~1 minecraft:redstone_wire
setblock ~9 ~6 ~1 minecraft:redstone_wire
setblock ~10 ~6 ~1 minecraft:redstone_wire
setblock ~11 ~6 ~1 minecraft:redstone_wire
setblock ~12 ~6 ~1 minecraft:redstone_wire
setblock ~13 ~6 ~1 minecraft:redstone_wire
