fill ~0 ~0 ~0 ~16 ~0 ~0 minecraft:smooth_stone
fill ~0 ~0 ~1 ~6 ~0 ~1 minecraft:smooth_stone
fill ~7 ~0 ~1 ~14 ~0 ~1 minecraft:obsidian
fill ~15 ~0 ~1 ~16 ~0 ~1 minecraft:smooth_stone
fill ~0 ~0 ~2 ~16 ~0 ~2 minecraft:smooth_stone
fill ~0 ~0 ~3 ~16 ~0 ~3 minecraft:smooth_stone
fill ~0 ~0 ~4 ~16 ~0 ~4 minecraft:smooth_stone
fill ~0 ~0 ~5 ~16 ~0 ~5 minecraft:smooth_stone
fill ~0 ~0 ~6 ~16 ~0 ~6 minecraft:smooth_stone
fill ~8 ~1 ~1 ~9 ~1 ~1 minecraft:slime_block
setblock ~13 ~1 ~1 minecraft:honey_block
setblock ~7 ~1 ~2 minecraft:smooth_stone
setblock ~14 ~1 ~2 minecraft:smooth_stone
fill ~7 ~1 ~3 ~11 ~1 ~3 minecraft:smooth_stone
setblock ~14 ~1 ~3 minecraft:smooth_stone
setblock ~7 ~1 ~4 minecraft:smooth_stone
setblock ~11 ~1 ~4 minecraft:smooth_stone
setblock ~14 ~1 ~4 minecraft:smooth_stone
fill ~0 ~1 ~5 ~14 ~1 ~5 minecraft:smooth_stone
setblock ~11 ~1 ~6 minecraft:smooth_stone
setblock ~7 ~2 ~1 minecraft:sticky_piston[facing=east]
fill ~8 ~2 ~1 ~9 ~2 ~1 minecraft:slime_block
setblock ~13 ~2 ~1 minecraft:honey_block
setblock ~14 ~2 ~1 minecraft:sticky_piston[facing=west]
setblock ~0 ~2 ~4 minecraft:smooth_stone
fill ~8 ~3 ~1 ~9 ~3 ~1 minecraft:slime_block
setblock ~13 ~3 ~1 minecraft:honey_block
setblock ~0 ~3 ~3 minecraft:smooth_stone
setblock ~8 ~4 ~1 minecraft:sticky_piston[facing=east]
setblock ~9 ~4 ~1 minecraft:slime_block
fill ~12 ~4 ~1 ~13 ~4 ~1 minecraft:obsidian
fill ~0 ~4 ~2 ~7 ~4 ~2 minecraft:smooth_stone
fill ~8 ~4 ~2 ~9 ~4 ~2 minecraft:obsidian
setblock ~7 ~2 ~2 minecraft:repeater[facing=south,delay=1]
setblock ~14 ~2 ~2 minecraft:repeater[facing=south,delay=1]
setblock ~7 ~2 ~3 minecraft:redstone_wire
setblock ~8 ~2 ~3 minecraft:repeater[facing=east,delay=4]
setblock ~9 ~2 ~3 minecraft:repeater[facing=east,delay=4]
setblock ~10 ~2 ~3 minecraft:repeater[facing=east,delay=4]
setblock ~11 ~2 ~3 minecraft:redstone_wire
setblock ~14 ~2 ~3 minecraft:redstone_wire
setblock ~7 ~2 ~4 minecraft:repeater[facing=south,delay=1]
setblock ~11 ~2 ~4 minecraft:redstone_wire
setblock ~14 ~2 ~4 minecraft:redstone_wire
setblock ~0 ~2 ~5 minecraft:redstone_wire
setblock ~1 ~2 ~5 minecraft:repeater[facing=east,delay=4]
setblock ~2 ~2 ~5 minecraft:repeater[facing=east,delay=4]
setblock ~3 ~2 ~5 minecraft:redstone_wire
setblock ~4 ~2 ~5 minecraft:redstone_wire
setblock ~5 ~2 ~5 minecraft:redstone_wire
setblock ~6 ~2 ~5 minecraft:redstone_wire
setblock ~7 ~2 ~5 minecraft:redstone_wire
setblock ~8 ~2 ~5 minecraft:redstone_wire
setblock ~9 ~2 ~5 minecraft:redstone_wire
setblock ~10 ~2 ~5 minecraft:redstone_wire
setblock ~11 ~2 ~5 minecraft:redstone_wire
setblock ~12 ~2 ~5 minecraft:redstone_wire
setblock ~13 ~2 ~5 minecraft:redstone_wire
setblock ~14 ~2 ~5 minecraft:redstone_wire
setblock ~11 ~2 ~6 minecraft:lever[face=floor,facing=north,powered=false]
setblock ~0 ~3 ~4 minecraft:redstone_wire
setblock ~0 ~4 ~3 minecraft:redstone_wire
setblock ~0 ~5 ~2 minecraft:redstone_wire
setblock ~1 ~5 ~2 minecraft:redstone_wire
setblock ~2 ~5 ~2 minecraft:redstone_wire
setblock ~3 ~5 ~2 minecraft:redstone_wire
setblock ~4 ~5 ~2 minecraft:redstone_wire
setblock ~5 ~5 ~2 minecraft:redstone_wire
setblock ~6 ~5 ~2 minecraft:redstone_wire
setblock ~7 ~5 ~2 minecraft:redstone_wire
setblock ~8 ~5 ~2 minecraft:redstone_wire
setblock ~9 ~5 ~2 minecraft:redstone_wire
