fill ~-3 ~0 ~-3 ~13 ~17 ~13 minecraft:air
fill ~-3 ~-1 ~-3 ~3 ~-1 ~-3 minecraft:grass_block
setblock ~4 ~-1 ~-3 minecraft:cobblestone
setblock ~6 ~-1 ~-3 minecraft:cobblestone
fill ~7 ~-1 ~-3 ~13 ~-1 ~-3 minecraft:grass_block
fill ~-3 ~-1 ~-2 ~3 ~-1 ~-2 minecraft:grass_block
setblock ~5 ~-1 ~-2 minecraft:stone_bricks
fill ~7 ~-1 ~-2 ~13 ~-1 ~-2 minecraft:grass_block
fill ~-3 ~-1 ~-1 ~13 ~-1 ~-1 minecraft:grass_block
fill ~-3 ~-1 ~0 ~-1 ~-1 ~0 minecraft:grass_block
fill ~0 ~-1 ~0 ~10 ~-1 ~0 minecraft:stone_bricks
fill ~11 ~-1 ~0 ~13 ~-1 ~0 minecraft:grass_block
fill ~-3 ~-1 ~1 ~-1 ~-1 ~1 minecraft:grass_block
fill ~0 ~-1 ~1 ~10 ~-1 ~1 minecraft:stone_bricks
fill ~11 ~-1 ~1 ~13 ~-1 ~1 minecraft:grass_block
fill ~-3 ~-1 ~2 ~-1 ~-1 ~2 minecraft:grass_block
fill ~0 ~-1 ~2 ~10 ~-1 ~2 minecraft:stone_bricks
fill ~11 ~-1 ~2 ~13 ~-1 ~2 minecraft:grass_block
fill ~-3 ~-1 ~3 ~-1 ~-1 ~3 minecraft:grass_block
fill ~0 ~-1 ~3 ~10 ~-1 ~3 minecraft:stone_bricks
fill ~11 ~-1 ~3 ~13 ~-1 ~3 minecraft:grass_block
fill ~-3 ~-1 ~4 ~-1 ~-1 ~4 minecraft:grass_block
fill ~0 ~-1 ~4 ~10 ~-1 ~4 minecraft:stone_bricks
fill ~11 ~-1 ~4 ~13 ~-1 ~4 minecraft:grass_block
fill ~-3 ~-1 ~5 ~-1 ~-1 ~5 minecraft:grass_block
fill ~0 ~-1 ~5 ~10 ~-1 ~5 minecraft:stone_bricks
fill ~11 ~-1 ~5 ~13 ~-1 ~5 minecraft:grass_block
fill ~-3 ~-1 ~6 ~-1 ~-1 ~6 minecraft:grass_block
fill ~0 ~-1 ~6 ~10 ~-1 ~6 minecraft:stone_bricks
fill ~11 ~-1 ~6 ~13 ~-1 ~6 minecraft:grass_block
fill ~-3 ~-1 ~7 ~-1 ~-1 ~7 minecraft:grass_block
fill ~0 ~-1 ~7 ~10 ~-1 ~7 minecraft:stone_bricks
fill ~11 ~-1 ~7 ~13 ~-1 ~7 minecraft:grass_block
fill ~-3 ~-1 ~8 ~-1 ~-1 ~8 minecraft:grass_block
fill ~0 ~-1 ~8 ~10 ~-1 ~8 minecraft:stone_bricks
fill ~11 ~-1 ~8 ~13 ~-1 ~8 minecraft:grass_block
fill ~-3 ~-1 ~9 ~-1 ~-1 ~9 minecraft:grass_block
fill ~0 ~-1 ~9 ~10 ~-1 ~9 minecraft:stone_bricks
fill ~11 ~-1 ~9 ~13 ~-1 ~9 minecraft:grass_block
fill ~-3 ~-1 ~10 ~-1 ~-1 ~10 minecraft:grass_block
fill ~0 ~-1 ~10 ~10 ~-1 ~10 minecraft:stone_bricks
fill ~11 ~-1 ~10 ~13 ~-1 ~10 minecraft:grass_block
fill ~-3 ~-1 ~11 ~13 ~-1 ~11 minecraft:grass_block
fill ~-3 ~-1 ~12 ~13 ~-1 ~12 minecraft:grass_block
fill ~-3 ~-1 ~13 ~13 ~-1 ~13 minecraft:grass_block
setblock ~3 ~0 ~-3 minecraft:stripped_dark_oak_log[axis=y]
setblock ~7 ~0 ~-3 minecraft:stripped_dark_oak_log[axis=y]
setblock ~5 ~0 ~-1 minecraft:stone_brick_stairs[facing=south,half=bottom]
fill ~0 ~0 ~0 ~10 ~0 ~0 minecraft:stone_bricks
setblock ~0 ~0 ~1 minecraft:stone_bricks
fill ~1 ~0 ~1 ~2 ~0 ~1 minecraft:dark_oak_planks
setblock ~3 ~0 ~1 minecraft:spruce_planks
fill ~4 ~0 ~1 ~5 ~0 ~1 minecraft:dark_oak_planks
setblock ~6 ~0 ~1 minecraft:spruce_planks
fill ~7 ~0 ~1 ~8 ~0 ~1 minecraft:dark_oak_planks
setblock ~9 ~0 ~1 minecraft:spruce_planks
setblock ~10 ~0 ~1 minecraft:stone_bricks
setblock ~0 ~0 ~2 minecraft:stone_bricks
fill ~1 ~0 ~2 ~2 ~0 ~2 minecraft:dark_oak_planks
setblock ~3 ~0 ~2 minecraft:spruce_planks
fill ~4 ~0 ~2 ~5 ~0 ~2 minecraft:dark_oak_planks
setblock ~6 ~0 ~2 minecraft:spruce_planks
fill ~7 ~0 ~2 ~8 ~0 ~2 minecraft:dark_oak_planks
setblock ~9 ~0 ~2 minecraft:spruce_planks
setblock ~10 ~0 ~2 minecraft:stone_bricks
setblock ~0 ~0 ~3 minecraft:stone_bricks
fill ~1 ~0 ~3 ~2 ~0 ~3 minecraft:dark_oak_planks
setblock ~3 ~0 ~3 minecraft:spruce_planks
fill ~4 ~0 ~3 ~5 ~0 ~3 minecraft:dark_oak_planks
setblock ~6 ~0 ~3 minecraft:spruce_planks
fill ~7 ~0 ~3 ~8 ~0 ~3 minecraft:dark_oak_planks
setblock ~9 ~0 ~3 minecraft:spruce_planks
setblock ~10 ~0 ~3 minecraft:stone_bricks
setblock ~0 ~0 ~4 minecraft:stone_bricks
fill ~1 ~0 ~4 ~2 ~0 ~4 minecraft:dark_oak_planks
setblock ~3 ~0 ~4 minecraft:spruce_planks
fill ~4 ~0 ~4 ~6 ~0 ~4 minecraft:moss_block
fill ~7 ~0 ~4 ~8 ~0 ~4 minecraft:dark_oak_planks
setblock ~9 ~0 ~4 minecraft:spruce_planks
setblock ~10 ~0 ~4 minecraft:stone_bricks
setblock ~0 ~0 ~5 minecraft:stone_bricks
fill ~1 ~0 ~5 ~2 ~0 ~5 minecraft:dark_oak_planks
setblock ~3 ~0 ~5 minecraft:spruce_planks
setblock ~4 ~0 ~5 minecraft:moss_block
setblock ~5 ~0 ~5 minecraft:cherry_log[axis=y]
setblock ~6 ~0 ~5 minecraft:moss_block
fill ~7 ~0 ~5 ~8 ~0 ~5 minecraft:dark_oak_planks
setblock ~9 ~0 ~5 minecraft:spruce_planks
setblock ~10 ~0 ~5 minecraft:stone_bricks
setblock ~0 ~0 ~6 minecraft:stone_bricks
fill ~1 ~0 ~6 ~2 ~0 ~6 minecraft:dark_oak_planks
setblock ~3 ~0 ~6 minecraft:spruce_planks
fill ~4 ~0 ~6 ~6 ~0 ~6 minecraft:moss_block
fill ~7 ~0 ~6 ~8 ~0 ~6 minecraft:dark_oak_planks
setblock ~9 ~0 ~6 minecraft:spruce_planks
setblock ~10 ~0 ~6 minecraft:stone_bricks
setblock ~0 ~0 ~7 minecraft:stone_bricks
fill ~1 ~0 ~7 ~2 ~0 ~7 minecraft:dark_oak_planks
setblock ~3 ~0 ~7 minecraft:spruce_planks
fill ~4 ~0 ~7 ~5 ~0 ~7 minecraft:dark_oak_planks
setblock ~6 ~0 ~7 minecraft:spruce_planks
fill ~7 ~0 ~7 ~8 ~0 ~7 minecraft:dark_oak_planks
setblock ~9 ~0 ~7 minecraft:spruce_planks
setblock ~10 ~0 ~7 minecraft:stone_bricks
setblock ~0 ~0 ~8 minecraft:stone_bricks
fill ~1 ~0 ~8 ~2 ~0 ~8 minecraft:dark_oak_planks
setblock ~3 ~0 ~8 minecraft:spruce_planks
fill ~4 ~0 ~8 ~5 ~0 ~8 minecraft:dark_oak_planks
setblock ~6 ~0 ~8 minecraft:spruce_planks
fill ~7 ~0 ~8 ~8 ~0 ~8 minecraft:dark_oak_planks
setblock ~9 ~0 ~8 minecraft:spruce_planks
setblock ~10 ~0 ~8 minecraft:stone_bricks
setblock ~0 ~0 ~9 minecraft:stone_bricks
fill ~1 ~0 ~9 ~2 ~0 ~9 minecraft:dark_oak_planks
setblock ~3 ~0 ~9 minecraft:spruce_planks
fill ~4 ~0 ~9 ~5 ~0 ~9 minecraft:dark_oak_planks
setblock ~6 ~0 ~9 minecraft:spruce_planks
fill ~7 ~0 ~9 ~8 ~0 ~9 minecraft:dark_oak_planks
setblock ~9 ~0 ~9 minecraft:spruce_planks
setblock ~10 ~0 ~9 minecraft:stone_bricks
fill ~0 ~0 ~10 ~10 ~0 ~10 minecraft:stone_bricks
setblock ~3 ~1 ~-3 minecraft:stripped_dark_oak_log[axis=y]
setblock ~7 ~1 ~-3 minecraft:stripped_dark_oak_log[axis=y]
setblock ~4 ~1 ~-1 minecraft:stripped_dark_oak_log[axis=y]
setblock ~6 ~1 ~-1 minecraft:stripped_dark_oak_log[axis=y]
setblock ~0 ~1 ~0 minecraft:stripped_dark_oak_log[axis=y]
setblock ~1 ~1 ~0 minecraft:mossy_stone_bricks
setblock ~2 ~1 ~0 minecraft:cobblestone
setblock ~3 ~1 ~0 minecraft:mossy_stone_bricks
setblock ~4 ~1 ~0 minecraft:stripped_dark_oak_log[axis=y]
setblock ~6 ~1 ~0 minecraft:stripped_dark_oak_log[axis=y]
setblock ~7 ~1 ~0 minecraft:mossy_cobblestone
setblock ~8 ~1 ~0 minecraft:stone_bricks
setblock ~9 ~1 ~0 minecraft:mossy_cobblestone
setblock ~10 ~1 ~0 minecraft:stripped_dark_oak_log[axis=y]
setblock ~0 ~1 ~1 minecraft:mossy_cobblestone
setblock ~6 ~1 ~1 minecraft:blast_furnace[facing=south]
setblock ~7 ~1 ~1 minecraft:smoker[facing=south]
setblock ~8 ~1 ~1 minecraft:furnace[facing=south]
setblock ~9 ~1 ~1 minecraft:crafting_table
setblock ~10 ~1 ~1 minecraft:mossy_stone_bricks
setblock ~0 ~1 ~2 minecraft:cobblestone
setblock ~8 ~1 ~2 minecraft:cauldron
setblock ~9 ~1 ~2 minecraft:barrel[facing=up]
setblock ~10 ~1 ~2 minecraft:stone_bricks
setblock ~0 ~1 ~3 minecraft:stripped_dark_oak_log[axis=y]
setblock ~3 ~1 ~3 minecraft:cherry_slab[type=bottom]
setblock ~4 ~1 ~3 minecraft:cherry_stairs[facing=north,half=bottom]
setblock ~6 ~1 ~3 minecraft:cherry_stairs[facing=north,half=bottom]
setblock ~7 ~1 ~3 minecraft:cherry_slab[type=bottom]
setblock ~10 ~1 ~3 minecraft:mossy_stone_bricks
setblock ~0 ~1 ~4 minecraft:stone_bricks
setblock ~3 ~1 ~4 minecraft:cherry_stairs[facing=west,half=bottom]
setblock ~7 ~1 ~4 minecraft:cherry_stairs[facing=east,half=bottom]
setblock ~9 ~1 ~4 minecraft:cherry_stairs[facing=north,half=bottom]
setblock ~10 ~1 ~4 minecraft:stone_bricks
setblock ~0 ~1 ~5 minecraft:mossy_cobblestone
setblock ~3 ~1 ~5 minecraft:cherry_stairs[facing=west,half=bottom]
setblock ~5 ~1 ~5 minecraft:cherry_log[axis=y]
setblock ~7 ~1 ~5 minecraft:cherry_stairs[facing=east,half=bottom]
setblock ~9 ~1 ~5 minecraft:cherry_fence[north=false,east=true,south=false,west=false,waterlogged=false]
setblock ~10 ~1 ~5 minecraft:stone_bricks
setblock ~0 ~1 ~6 minecraft:stone_bricks
setblock ~3 ~1 ~6 minecraft:cherry_stairs[facing=west,half=bottom]
setblock ~7 ~1 ~6 minecraft:cherry_stairs[facing=east,half=bottom]
setblock ~9 ~1 ~6 minecraft:cherry_stairs[facing=south,half=bottom]
setblock ~10 ~1 ~6 minecraft:cobblestone
setblock ~0 ~1 ~7 minecraft:stripped_dark_oak_log[axis=y]
setblock ~3 ~1 ~7 minecraft:cherry_slab[type=bottom]
setblock ~4 ~1 ~7 minecraft:cherry_stairs[facing=south,half=bottom]
setblock ~5 ~1 ~7 minecraft:cherry_stairs[facing=south,half=bottom]
setblock ~6 ~1 ~7 minecraft:cherry_stairs[facing=south,half=bottom]
setblock ~7 ~1 ~7 minecraft:cherry_slab[type=bottom]
setblock ~9 ~1 ~7 minecraft:chest[facing=west,type=single]
setblock ~10 ~1 ~7 minecraft:mossy_stone_bricks
setblock ~0 ~1 ~8 minecraft:stone_bricks
setblock ~1 ~1 ~8 minecraft:bookshelf
setblock ~9 ~1 ~8 minecraft:chest[facing=west,type=single]
setblock ~10 ~1 ~8 minecraft:stone_bricks
setblock ~0 ~1 ~9 minecraft:stone_bricks
setblock ~1 ~1 ~9 minecraft:bookshelf
setblock ~2 ~1 ~9 minecraft:lectern[facing=east]
fill ~4 ~1 ~9 ~6 ~1 ~9 minecraft:cherry_planks
setblock ~7 ~1 ~9 minecraft:cherry_stairs[facing=west,half=bottom]
setblock ~8 ~1 ~9 minecraft:chest[facing=north,type=single]
setblock ~9 ~1 ~9 minecraft:chest[facing=west,type=single]
setblock ~10 ~1 ~9 minecraft:mossy_stone_bricks
setblock ~0 ~1 ~10 minecraft:stripped_dark_oak_log[axis=y]
setblock ~1 ~1 ~10 minecraft:mossy_stone_bricks
setblock ~2 ~1 ~10 minecraft:stone_bricks
setblock ~3 ~1 ~10 minecraft:stripped_dark_oak_log[axis=y]
setblock ~4 ~1 ~10 minecraft:stone_bricks
setblock ~5 ~1 ~10 minecraft:mossy_stone_bricks
setblock ~6 ~1 ~10 minecraft:stone_bricks
setblock ~7 ~1 ~10 minecraft:stripped_dark_oak_log[axis=y]
fill ~8 ~1 ~10 ~9 ~1 ~10 minecraft:stone_bricks
setblock ~10 ~1 ~10 minecraft:stripped_dark_oak_log[axis=y]
setblock ~4 ~2 ~-1 minecraft:stripped_dark_oak_log[axis=y]
setblock ~6 ~2 ~-1 minecraft:stripped_dark_oak_log[axis=y]
setblock ~0 ~2 ~0 minecraft:stripped_dark_oak_log[axis=y]
setblock ~1 ~2 ~0 minecraft:calcite
setblock ~2 ~2 ~0 minecraft:glass_pane[north=false,east=true,south=false,west=true,waterlogged=false]
setblock ~3 ~2 ~0 minecraft:calcite
setblock ~4 ~2 ~0 minecraft:stripped_dark_oak_log[axis=y]
setblock ~6 ~2 ~0 minecraft:stripped_dark_oak_log[axis=y]
setblock ~7 ~2 ~0 minecraft:calcite
setblock ~8 ~2 ~0 minecraft:glass_pane[north=false,east=true,south=false,west=true,waterlogged=false]
setblock ~9 ~2 ~0 minecraft:calcite
setblock ~10 ~2 ~0 minecraft:stripped_dark_oak_log[axis=y]
setblock ~0 ~2 ~1 minecraft:calcite
setblock ~10 ~2 ~1 minecraft:glass_pane[north=true,east=false,south=true,west=false,waterlogged=false]
setblock ~0 ~2 ~2 minecraft:glass_pane[north=true,east=false,south=true,west=false,waterlogged=false]
setblock ~9 ~2 ~2 minecraft:barrel[facing=up]
setblock ~10 ~2 ~2 minecraft:glass_pane[north=true,east=false,south=true,west=false,waterlogged=false]
setblock ~0 ~2 ~3 minecraft:stripped_dark_oak_log[axis=y]
setblock ~10 ~2 ~3 minecraft:stripped_dark_oak_log[axis=y]
setblock ~0 ~2 ~4 minecraft:glass_pane[north=true,east=false,south=true,west=false,waterlogged=false]
setblock ~10 ~2 ~4 minecraft:glass_pane[north=true,east=false,south=true,west=false,waterlogged=false]
setblock ~0 ~2 ~5 minecraft:glass_pane[north=true,east=false,south=true,west=false,waterlogged=false]
setblock ~5 ~2 ~5 minecraft:cherry_log[axis=y]
setblock ~10 ~2 ~5 minecraft:stripped_dark_oak_log[axis=y]
setblock ~0 ~2 ~6 minecraft:glass_pane[north=true,east=false,south=true,west=false,waterlogged=false]
setblock ~10 ~2 ~6 minecraft:glass_pane[north=true,east=false,south=true,west=false,waterlogged=false]
setblock ~0 ~2 ~7 minecraft:stripped_dark_oak_log[axis=y]
setblock ~10 ~2 ~7 minecraft:stripped_dark_oak_log[axis=y]
setblock ~0 ~2 ~8 minecraft:glass_pane[north=true,east=true,south=true,west=false,waterlogged=false]
setblock ~1 ~2 ~8 minecraft:bookshelf
setblock ~9 ~2 ~8 minecraft:barrel[facing=up]
setblock ~10 ~2 ~8 minecraft:glass_pane[north=true,east=false,south=true,west=false,waterlogged=false]
setblock ~0 ~2 ~9 minecraft:calcite
setblock ~1 ~2 ~9 minecraft:bookshelf
fill ~4 ~2 ~9 ~5 ~2 ~9 minecraft:cherry_planks
setblock ~6 ~2 ~9 minecraft:cherry_stairs[facing=west,half=bottom]
setblock ~9 ~2 ~9 minecraft:barrel[facing=up]
setblock ~10 ~2 ~9 minecraft:glass_pane[north=true,east=false,south=true,west=false,waterlogged=false]
setblock ~0 ~2 ~10 minecraft:stripped_dark_oak_log[axis=y]
setblock ~1 ~2 ~10 minecraft:glass_pane[north=true,east=true,south=false,west=true,waterlogged=false]
setblock ~2 ~2 ~10 minecraft:glass_pane[north=false,east=true,south=false,west=true,waterlogged=false]
setblock ~3 ~2 ~10 minecraft:stripped_dark_oak_log[axis=y]
setblock ~4 ~2 ~10 minecraft:glass_pane[north=true,east=true,south=false,west=true,waterlogged=false]
setblock ~5 ~2 ~10 minecraft:glass_pane[north=true,east=true,south=false,west=true,waterlogged=false]
setblock ~6 ~2 ~10 minecraft:glass_pane[north=false,east=true,south=false,west=true,waterlogged=false]
setblock ~7 ~2 ~10 minecraft:stripped_dark_oak_log[axis=y]
setblock ~8 ~2 ~10 minecraft:glass_pane[north=false,east=true,south=false,west=true,waterlogged=false]
setblock ~9 ~2 ~10 minecraft:glass_pane[north=false,east=true,south=false,west=true,waterlogged=false]
setblock ~10 ~2 ~10 minecraft:stripped_dark_oak_log[axis=y]
setblock ~4 ~3 ~-1 minecraft:stripped_dark_oak_log[axis=y]
setblock ~6 ~3 ~-1 minecraft:stripped_dark_oak_log[axis=y]
setblock ~0 ~3 ~0 minecraft:stripped_dark_oak_log[axis=y]
setblock ~1 ~3 ~0 minecraft:calcite
setblock ~2 ~3 ~0 minecraft:glass_pane[north=false,east=true,south=false,west=true,waterlogged=false]
setblock ~3 ~3 ~0 minecraft:calcite
setblock ~4 ~3 ~0 minecraft:stripped_dark_oak_log[axis=y]
setblock ~5 ~3 ~0 minecraft:glass_pane[north=false,east=true,south=false,west=true,waterlogged=false]
setblock ~6 ~3 ~0 minecraft:stripped_dark_oak_log[axis=y]
setblock ~7 ~3 ~0 minecraft:calcite
setblock ~8 ~3 ~0 minecraft:glass_pane[north=false,east=true,south=false,west=true,waterlogged=false]
setblock ~9 ~3 ~0 minecraft:calcite
setblock ~10 ~3 ~0 minecraft:stripped_dark_oak_log[axis=y]
setblock ~0 ~3 ~1 minecraft:calcite
setblock ~10 ~3 ~1 minecraft:glass_pane[north=true,east=false,south=true,west=false,waterlogged=false]
setblock ~0 ~3 ~2 minecraft:glass_pane[north=true,east=false,south=true,west=false,waterlogged=false]
setblock ~10 ~3 ~2 minecraft:glass_pane[north=true,east=false,south=true,west=false,waterlogged=false]
setblock ~0 ~3 ~3 minecraft:stripped_dark_oak_log[axis=y]
setblock ~10 ~3 ~3 minecraft:stripped_dark_oak_log[axis=y]
setblock ~0 ~3 ~4 minecraft:glass_pane[north=true,east=false,south=true,west=false,waterlogged=false]
setblock ~10 ~3 ~4 minecraft:glass_pane[north=true,east=false,south=true,west=false,waterlogged=false]
setblock ~0 ~3 ~5 minecraft:glass_pane[north=true,east=false,south=true,west=false,waterlogged=false]
setblock ~5 ~3 ~5 minecraft:cherry_log[axis=y]
setblock ~10 ~3 ~5 minecraft:stripped_dark_oak_log[axis=y]
setblock ~0 ~3 ~6 minecraft:glass_pane[north=true,east=false,south=true,west=false,waterlogged=false]
setblock ~10 ~3 ~6 minecraft:glass_pane[north=true,east=false,south=true,west=false,waterlogged=false]
setblock ~0 ~3 ~7 minecraft:stripped_dark_oak_log[axis=y]
setblock ~10 ~3 ~7 minecraft:stripped_dark_oak_log[axis=y]
setblock ~0 ~3 ~8 minecraft:glass_pane[north=true,east=true,south=true,west=false,waterlogged=false]
setblock ~1 ~3 ~8 minecraft:bookshelf
setblock ~10 ~3 ~8 minecraft:glass_pane[north=true,east=false,south=true,west=false,waterlogged=false]
setblock ~0 ~3 ~9 minecraft:calcite
setblock ~1 ~3 ~9 minecraft:bookshelf
setblock ~4 ~3 ~9 minecraft:cherry_planks
setblock ~5 ~3 ~9 minecraft:cherry_stairs[facing=west,half=bottom]
setblock ~10 ~3 ~9 minecraft:glass_pane[north=true,east=false,south=true,west=false,waterlogged=false]
setblock ~0 ~3 ~10 minecraft:stripped_dark_oak_log[axis=y]
setblock ~1 ~3 ~10 minecraft:glass_pane[north=true,east=true,south=false,west=true,waterlogged=false]
setblock ~2 ~3 ~10 minecraft:glass_pane[north=false,east=true,south=false,west=true,waterlogged=false]
setblock ~3 ~3 ~10 minecraft:stripped_dark_oak_log[axis=y]
setblock ~4 ~3 ~10 minecraft:glass_pane[north=true,east=true,south=false,west=true,waterlogged=false]
setblock ~5 ~3 ~10 minecraft:glass_pane[north=false,east=true,south=false,west=true,waterlogged=false]
setblock ~6 ~3 ~10 minecraft:glass_pane[north=false,east=true,south=false,west=true,waterlogged=false]
setblock ~7 ~3 ~10 minecraft:stripped_dark_oak_log[axis=y]
setblock ~8 ~3 ~10 minecraft:glass_pane[north=false,east=true,south=false,west=true,waterlogged=false]
setblock ~9 ~3 ~10 minecraft:glass_pane[north=false,east=true,south=false,west=true,waterlogged=false]
setblock ~10 ~3 ~10 minecraft:stripped_dark_oak_log[axis=y]
setblock ~3 ~4 ~-2 minecraft:cherry_slab[type=bottom]
setblock ~4 ~4 ~-2 minecraft:cherry_slab[type=bottom]
setblock ~5 ~4 ~-2 minecraft:cherry_slab[type=bottom]
setblock ~6 ~4 ~-2 minecraft:cherry_slab[type=bottom]
setblock ~7 ~4 ~-2 minecraft:cherry_slab[type=bottom]
setblock ~-1 ~4 ~-1 minecraft:dark_oak_slab[type=top]
setblock ~0 ~4 ~-1 minecraft:dark_oak_slab[type=top]
setblock ~1 ~4 ~-1 minecraft:dark_oak_slab[type=top]
setblock ~2 ~4 ~-1 minecraft:dark_oak_slab[type=top]
setblock ~3 ~4 ~-1 minecraft:cherry_slab[type=bottom]
setblock ~4 ~4 ~-1 minecraft:cherry_slab[type=bottom]
setblock ~5 ~4 ~-1 minecraft:cherry_slab[type=bottom]
setblock ~6 ~4 ~-1 minecraft:cherry_slab[type=bottom]
setblock ~7 ~4 ~-1 minecraft:cherry_slab[type=bottom]
setblock ~8 ~4 ~-1 minecraft:dark_oak_slab[type=top]
setblock ~9 ~4 ~-1 minecraft:dark_oak_slab[type=top]
setblock ~10 ~4 ~-1 minecraft:dark_oak_slab[type=top]
setblock ~11 ~4 ~-1 minecraft:dark_oak_slab[type=top]
setblock ~0 ~4 ~0 minecraft:stripped_dark_oak_log[axis=x]
setblock ~1 ~4 ~0 minecraft:stripped_dark_oak_log[axis=x]
setblock ~2 ~4 ~0 minecraft:stripped_dark_oak_log[axis=x]
setblock ~3 ~4 ~0 minecraft:stripped_dark_oak_log[axis=x]
setblock ~4 ~4 ~0 minecraft:stripped_dark_oak_log[axis=x]
setblock ~5 ~4 ~0 minecraft:stripped_dark_oak_log[axis=x]
setblock ~6 ~4 ~0 minecraft:stripped_dark_oak_log[axis=x]
setblock ~7 ~4 ~0 minecraft:stripped_dark_oak_log[axis=x]
setblock ~8 ~4 ~0 minecraft:stripped_dark_oak_log[axis=x]
setblock ~9 ~4 ~0 minecraft:stripped_dark_oak_log[axis=x]
setblock ~10 ~4 ~0 minecraft:stripped_dark_oak_log[axis=x]
setblock ~0 ~4 ~1 minecraft:stripped_dark_oak_log[axis=z]
fill ~1 ~4 ~1 ~3 ~4 ~1 minecraft:spruce_planks
setblock ~10 ~4 ~1 minecraft:stripped_dark_oak_log[axis=z]
setblock ~0 ~4 ~2 minecraft:stripped_dark_oak_log[axis=z]
fill ~1 ~4 ~2 ~3 ~4 ~2 minecraft:spruce_planks
setblock ~10 ~4 ~2 minecraft:stripped_dark_oak_log[axis=z]
setblock ~0 ~4 ~3 minecraft:stripped_dark_oak_log[axis=z]
fill ~1 ~4 ~3 ~3 ~4 ~3 minecraft:spruce_planks
setblock ~10 ~4 ~3 minecraft:stripped_dark_oak_log[axis=z]
setblock ~0 ~4 ~4 minecraft:stripped_dark_oak_log[axis=z]
fill ~1 ~4 ~4 ~3 ~4 ~4 minecraft:spruce_planks
setblock ~10 ~4 ~4 minecraft:stripped_dark_oak_log[axis=z]
setblock ~0 ~4 ~5 minecraft:stripped_dark_oak_log[axis=z]
fill ~1 ~4 ~5 ~3 ~4 ~5 minecraft:spruce_planks
setblock ~5 ~4 ~5 minecraft:cherry_log[axis=y]
setblock ~10 ~4 ~5 minecraft:stripped_dark_oak_log[axis=z]
setblock ~0 ~4 ~6 minecraft:stripped_dark_oak_log[axis=z]
fill ~1 ~4 ~6 ~3 ~4 ~6 minecraft:spruce_planks
setblock ~10 ~4 ~6 minecraft:stripped_dark_oak_log[axis=z]
setblock ~0 ~4 ~7 minecraft:stripped_dark_oak_log[axis=z]
fill ~1 ~4 ~7 ~3 ~4 ~7 minecraft:spruce_planks
setblock ~10 ~4 ~7 minecraft:stripped_dark_oak_log[axis=z]
setblock ~0 ~4 ~8 minecraft:stripped_dark_oak_log[axis=z]
fill ~1 ~4 ~8 ~3 ~4 ~8 minecraft:spruce_planks
setblock ~10 ~4 ~8 minecraft:stripped_dark_oak_log[axis=z]
setblock ~0 ~4 ~9 minecraft:stripped_dark_oak_log[axis=z]
fill ~1 ~4 ~9 ~3 ~4 ~9 minecraft:spruce_planks
setblock ~4 ~4 ~9 minecraft:cherry_stairs[facing=west,half=bottom]
setblock ~10 ~4 ~9 minecraft:stripped_dark_oak_log[axis=z]
setblock ~0 ~4 ~10 minecraft:stripped_dark_oak_log[axis=x]
setblock ~1 ~4 ~10 minecraft:stripped_dark_oak_log[axis=x]
setblock ~2 ~4 ~10 minecraft:stripped_dark_oak_log[axis=x]
setblock ~3 ~4 ~10 minecraft:stripped_dark_oak_log[axis=x]
setblock ~4 ~4 ~10 minecraft:stripped_dark_oak_log[axis=x]
setblock ~5 ~4 ~10 minecraft:stripped_dark_oak_log[axis=x]
setblock ~6 ~4 ~10 minecraft:stripped_dark_oak_log[axis=x]
setblock ~7 ~4 ~10 minecraft:stripped_dark_oak_log[axis=x]
setblock ~8 ~4 ~10 minecraft:stripped_dark_oak_log[axis=x]
setblock ~9 ~4 ~10 minecraft:stripped_dark_oak_log[axis=x]
setblock ~10 ~4 ~10 minecraft:stripped_dark_oak_log[axis=x]
setblock ~-1 ~4 ~11 minecraft:dark_oak_slab[type=top]
setblock ~0 ~4 ~11 minecraft:dark_oak_slab[type=top]
setblock ~1 ~4 ~11 minecraft:dark_oak_slab[type=top]
setblock ~2 ~4 ~11 minecraft:dark_oak_slab[type=top]
setblock ~3 ~4 ~11 minecraft:dark_oak_slab[type=top]
setblock ~4 ~4 ~11 minecraft:dark_oak_slab[type=top]
setblock ~5 ~4 ~11 minecraft:dark_oak_slab[type=top]
setblock ~6 ~4 ~11 minecraft:dark_oak_slab[type=top]
setblock ~7 ~4 ~11 minecraft:dark_oak_slab[type=top]
setblock ~8 ~4 ~11 minecraft:dark_oak_slab[type=top]
setblock ~9 ~4 ~11 minecraft:dark_oak_slab[type=top]
setblock ~10 ~4 ~11 minecraft:dark_oak_slab[type=top]
setblock ~11 ~4 ~11 minecraft:dark_oak_slab[type=top]
setblock ~-1 ~5 ~-1 minecraft:cherry_stairs[facing=south,half=bottom]
setblock ~0 ~5 ~-1 minecraft:cherry_stairs[facing=south,half=bottom]
setblock ~1 ~5 ~-1 minecraft:cherry_stairs[facing=south,half=bottom]
setblock ~2 ~5 ~-1 minecraft:cherry_stairs[facing=south,half=bottom]
setblock ~3 ~5 ~-1 minecraft:cherry_stairs[facing=south,half=bottom]
setblock ~4 ~5 ~-1 minecraft:cherry_stairs[facing=south,half=bottom]
setblock ~5 ~5 ~-1 minecraft:cherry_stairs[facing=south,half=bottom]
setblock ~6 ~5 ~-1 minecraft:cherry_stairs[facing=south,half=bottom]
setblock ~7 ~5 ~-1 minecraft:cherry_stairs[facing=south,half=bottom]
setblock ~8 ~5 ~-1 minecraft:cherry_stairs[facing=south,half=bottom]
setblock ~9 ~5 ~-1 minecraft:cherry_stairs[facing=south,half=bottom]
setblock ~10 ~5 ~-1 minecraft:cherry_stairs[facing=south,half=bottom]
setblock ~11 ~5 ~-1 minecraft:cherry_stairs[facing=south,half=bottom]
fill ~0 ~5 ~0 ~10 ~5 ~0 minecraft:calcite
setblock ~0 ~5 ~1 minecraft:stripped_dark_oak_log[axis=y]
setblock ~3 ~5 ~1 minecraft:cherry_fence[north=true,east=false,south=true,west=false,waterlogged=false]
setblock ~10 ~5 ~1 minecraft:glass_pane[north=true,east=false,south=true,west=false,waterlogged=false]
setblock ~0 ~5 ~2 minecraft:calcite
setblock ~3 ~5 ~2 minecraft:cherry_fence[north=true,east=false,south=true,west=false,waterlogged=false]
setblock ~10 ~5 ~2 minecraft:glass_pane[north=true,east=false,south=true,west=false,waterlogged=false]
setblock ~0 ~5 ~3 minecraft:stripped_dark_oak_log[axis=y]
setblock ~3 ~5 ~3 minecraft:cherry_fence[north=true,east=false,south=true,west=false,waterlogged=false]
setblock ~10 ~5 ~3 minecraft:stripped_dark_oak_log[axis=y]
setblock ~0 ~5 ~4 minecraft:calcite
setblock ~1 ~5 ~4 minecraft:bookshelf
setblock ~3 ~5 ~4 minecraft:cherry_fence[north=true,east=false,south=true,west=false,waterlogged=false]
setblock ~10 ~5 ~4 minecraft:glass_pane[north=true,east=false,south=true,west=false,waterlogged=false]
setblock ~0 ~5 ~5 minecraft:calcite
setblock ~1 ~5 ~5 minecraft:barrel[facing=up]
setblock ~3 ~5 ~5 minecraft:cherry_fence[north=true,east=false,south=true,west=false,waterlogged=false]
setblock ~5 ~5 ~5 minecraft:cherry_log[axis=y]
setblock ~10 ~5 ~5 minecraft:stripped_dark_oak_log[axis=y]
setblock ~0 ~5 ~6 minecraft:calcite
setblock ~1 ~5 ~6 minecraft:bookshelf
setblock ~3 ~5 ~6 minecraft:cherry_fence[north=true,east=false,south=true,west=false,waterlogged=false]
setblock ~10 ~5 ~6 minecraft:glass_pane[north=true,east=false,south=true,west=false,waterlogged=false]
setblock ~0 ~5 ~7 minecraft:stripped_dark_oak_log[axis=y]
setblock ~3 ~5 ~7 minecraft:cherry_fence[north=true,east=false,south=true,west=false,waterlogged=false]
setblock ~10 ~5 ~7 minecraft:stripped_dark_oak_log[axis=y]
setblock ~0 ~5 ~8 minecraft:calcite
setblock ~3 ~5 ~8 minecraft:cherry_fence[north=true,east=false,south=false,west=false,waterlogged=false]
setblock ~10 ~5 ~8 minecraft:glass_pane[north=true,east=false,south=true,west=false,waterlogged=false]
setblock ~0 ~5 ~9 minecraft:stripped_dark_oak_log[axis=y]
setblock ~10 ~5 ~9 minecraft:glass_pane[north=true,east=false,south=true,west=false,waterlogged=false]
fill ~0 ~5 ~10 ~10 ~5 ~10 minecraft:calcite
setblock ~-1 ~5 ~11 minecraft:cherry_stairs[facing=north,half=bottom]
setblock ~0 ~5 ~11 minecraft:cherry_stairs[facing=north,half=bottom]
setblock ~1 ~5 ~11 minecraft:cherry_stairs[facing=north,half=bottom]
setblock ~2 ~5 ~11 minecraft:cherry_stairs[facing=north,half=bottom]
setblock ~3 ~5 ~11 minecraft:cherry_stairs[facing=north,half=bottom]
setblock ~4 ~5 ~11 minecraft:cherry_stairs[facing=north,half=bottom]
setblock ~5 ~5 ~11 minecraft:cherry_stairs[facing=north,half=bottom]
setblock ~6 ~5 ~11 minecraft:cherry_stairs[facing=north,half=bottom]
setblock ~7 ~5 ~11 minecraft:cherry_stairs[facing=north,half=bottom]
setblock ~8 ~5 ~11 minecraft:cherry_stairs[facing=north,half=bottom]
setblock ~9 ~5 ~11 minecraft:cherry_stairs[facing=north,half=bottom]
setblock ~10 ~5 ~11 minecraft:cherry_stairs[facing=north,half=bottom]
setblock ~11 ~5 ~11 minecraft:cherry_stairs[facing=north,half=bottom]
setblock ~-1 ~6 ~0 minecraft:cherry_stairs[facing=south,half=bottom]
setblock ~0 ~6 ~0 minecraft:cherry_stairs[facing=south,half=bottom]
setblock ~1 ~6 ~0 minecraft:cherry_stairs[facing=south,half=bottom]
setblock ~2 ~6 ~0 minecraft:cherry_stairs[facing=south,half=bottom]
setblock ~3 ~6 ~0 minecraft:cherry_stairs[facing=south,half=bottom]
setblock ~4 ~6 ~0 minecraft:cherry_stairs[facing=south,half=bottom]
setblock ~5 ~6 ~0 minecraft:cherry_stairs[facing=south,half=bottom]
setblock ~6 ~6 ~0 minecraft:cherry_stairs[facing=south,half=bottom]
setblock ~7 ~6 ~0 minecraft:cherry_stairs[facing=south,half=bottom]
setblock ~8 ~6 ~0 minecraft:cherry_stairs[facing=south,half=bottom]
setblock ~9 ~6 ~0 minecraft:cherry_stairs[facing=south,half=bottom]
setblock ~10 ~6 ~0 minecraft:cherry_stairs[facing=south,half=bottom]
setblock ~11 ~6 ~0 minecraft:cherry_stairs[facing=south,half=bottom]
setblock ~0 ~6 ~1 minecraft:stripped_dark_oak_log[axis=y]
setblock ~10 ~6 ~1 minecraft:glass_pane[north=false,east=false,south=true,west=false,waterlogged=false]
setblock ~0 ~6 ~2 minecraft:calcite
setblock ~10 ~6 ~2 minecraft:glass_pane[north=true,east=false,south=true,west=false,waterlogged=false]
setblock ~0 ~6 ~3 minecraft:stripped_dark_oak_log[axis=y]
setblock ~10 ~6 ~3 minecraft:stripped_dark_oak_log[axis=y]
setblock ~0 ~6 ~4 minecraft:calcite
setblock ~1 ~6 ~4 minecraft:bookshelf
setblock ~10 ~6 ~4 minecraft:glass_pane[north=true,east=false,south=true,west=false,waterlogged=false]
setblock ~0 ~6 ~5 minecraft:calcite
setblock ~5 ~6 ~5 minecraft:cherry_log[axis=y]
setblock ~10 ~6 ~5 minecraft:stripped_dark_oak_log[axis=y]
setblock ~0 ~6 ~6 minecraft:calcite
setblock ~1 ~6 ~6 minecraft:bookshelf
setblock ~10 ~6 ~6 minecraft:glass_pane[north=true,east=false,south=true,west=false,waterlogged=false]
setblock ~0 ~6 ~7 minecraft:stripped_dark_oak_log[axis=y]
setblock ~10 ~6 ~7 minecraft:stripped_dark_oak_log[axis=y]
setblock ~0 ~6 ~8 minecraft:calcite
setblock ~10 ~6 ~8 minecraft:glass_pane[north=true,east=false,south=true,west=false,waterlogged=false]
setblock ~0 ~6 ~9 minecraft:stripped_dark_oak_log[axis=y]
setblock ~10 ~6 ~9 minecraft:glass_pane[north=true,east=false,south=false,west=false,waterlogged=false]
setblock ~-1 ~6 ~10 minecraft:cherry_stairs[facing=north,half=bottom]
setblock ~0 ~6 ~10 minecraft:cherry_stairs[facing=north,half=bottom]
setblock ~1 ~6 ~10 minecraft:cherry_stairs[facing=north,half=bottom]
setblock ~2 ~6 ~10 minecraft:cherry_stairs[facing=north,half=bottom]
setblock ~3 ~6 ~10 minecraft:cherry_stairs[facing=north,half=bottom]
setblock ~4 ~6 ~10 minecraft:cherry_stairs[facing=north,half=bottom]
setblock ~5 ~6 ~10 minecraft:cherry_stairs[facing=north,half=bottom]
setblock ~6 ~6 ~10 minecraft:cherry_stairs[facing=north,half=bottom]
setblock ~7 ~6 ~10 minecraft:cherry_stairs[facing=north,half=bottom]
setblock ~8 ~6 ~10 minecraft:cherry_stairs[facing=north,half=bottom]
setblock ~9 ~6 ~10 minecraft:cherry_stairs[facing=north,half=bottom]
setblock ~10 ~6 ~10 minecraft:cherry_stairs[facing=north,half=bottom]
setblock ~11 ~6 ~10 minecraft:cherry_stairs[facing=north,half=bottom]
setblock ~-1 ~7 ~1 minecraft:cherry_stairs[facing=south,half=bottom]
setblock ~0 ~7 ~1 minecraft:cherry_stairs[facing=south,half=bottom]
setblock ~1 ~7 ~1 minecraft:cherry_stairs[facing=south,half=bottom]
setblock ~2 ~7 ~1 minecraft:cherry_stairs[facing=south,half=bottom]
setblock ~3 ~7 ~1 minecraft:cherry_stairs[facing=south,half=bottom]
setblock ~4 ~7 ~1 minecraft:cherry_stairs[facing=south,half=bottom]
setblock ~5 ~7 ~1 minecraft:cherry_stairs[facing=south,half=bottom]
setblock ~6 ~7 ~1 minecraft:cherry_stairs[facing=south,half=bottom]
setblock ~7 ~7 ~1 minecraft:cherry_stairs[facing=south,half=bottom]
setblock ~8 ~7 ~1 minecraft:cherry_stairs[facing=south,half=bottom]
setblock ~9 ~7 ~1 minecraft:cherry_stairs[facing=south,half=bottom]
setblock ~10 ~7 ~1 minecraft:cherry_stairs[facing=south,half=bottom]
setblock ~11 ~7 ~1 minecraft:cherry_stairs[facing=south,half=bottom]
setblock ~0 ~7 ~2 minecraft:calcite
setblock ~3 ~7 ~2 minecraft:stripped_dark_oak_log[axis=z]
setblock ~7 ~7 ~2 minecraft:stripped_dark_oak_log[axis=z]
setblock ~10 ~7 ~2 minecraft:glass_pane[north=false,east=false,south=true,west=false,waterlogged=false]
setblock ~0 ~7 ~3 minecraft:stripped_dark_oak_log[axis=y]
setblock ~3 ~7 ~3 minecraft:stripped_dark_oak_log[axis=z]
setblock ~7 ~7 ~3 minecraft:stripped_dark_oak_log[axis=z]
setblock ~10 ~7 ~3 minecraft:stripped_dark_oak_log[axis=y]
setblock ~0 ~7 ~4 minecraft:glass_pane[north=true,east=false,south=true,west=false,waterlogged=false]
setblock ~3 ~7 ~4 minecraft:stripped_dark_oak_log[axis=z]
setblock ~7 ~7 ~4 minecraft:stripped_dark_oak_log[axis=z]
setblock ~10 ~7 ~4 minecraft:glass_pane[north=true,east=false,south=true,west=false,waterlogged=false]
setblock ~0 ~7 ~5 minecraft:glass_pane[north=true,east=false,south=true,west=false,waterlogged=false]
setblock ~3 ~7 ~5 minecraft:stripped_dark_oak_log[axis=z]
setblock ~5 ~7 ~5 minecraft:cherry_log[axis=y]
setblock ~7 ~7 ~5 minecraft:stripped_dark_oak_log[axis=z]
setblock ~10 ~7 ~5 minecraft:stripped_dark_oak_log[axis=y]
setblock ~0 ~7 ~6 minecraft:glass_pane[north=true,east=false,south=true,west=false,waterlogged=false]
setblock ~3 ~7 ~6 minecraft:stripped_dark_oak_log[axis=z]
setblock ~7 ~7 ~6 minecraft:stripped_dark_oak_log[axis=z]
setblock ~10 ~7 ~6 minecraft:glass_pane[north=true,east=false,south=true,west=false,waterlogged=false]
setblock ~0 ~7 ~7 minecraft:stripped_dark_oak_log[axis=y]
setblock ~3 ~7 ~7 minecraft:stripped_dark_oak_log[axis=z]
setblock ~7 ~7 ~7 minecraft:stripped_dark_oak_log[axis=z]
setblock ~10 ~7 ~7 minecraft:stripped_dark_oak_log[axis=y]
setblock ~0 ~7 ~8 minecraft:calcite
setblock ~3 ~7 ~8 minecraft:stripped_dark_oak_log[axis=z]
setblock ~7 ~7 ~8 minecraft:stripped_dark_oak_log[axis=z]
setblock ~10 ~7 ~8 minecraft:glass_pane[north=true,east=false,south=false,west=false,waterlogged=false]
setblock ~-1 ~7 ~9 minecraft:cherry_stairs[facing=north,half=bottom]
setblock ~0 ~7 ~9 minecraft:cherry_stairs[facing=north,half=bottom]
setblock ~1 ~7 ~9 minecraft:cherry_stairs[facing=north,half=bottom]
setblock ~2 ~7 ~9 minecraft:cherry_stairs[facing=north,half=bottom]
setblock ~3 ~7 ~9 minecraft:cherry_stairs[facing=north,half=bottom]
setblock ~4 ~7 ~9 minecraft:cherry_stairs[facing=north,half=bottom]
setblock ~5 ~7 ~9 minecraft:cherry_stairs[facing=north,half=bottom]
setblock ~6 ~7 ~9 minecraft:cherry_stairs[facing=north,half=bottom]
setblock ~7 ~7 ~9 minecraft:cherry_stairs[facing=north,half=bottom]
setblock ~8 ~7 ~9 minecraft:cherry_stairs[facing=north,half=bottom]
setblock ~9 ~7 ~9 minecraft:cherry_stairs[facing=north,half=bottom]
setblock ~10 ~7 ~9 minecraft:cherry_stairs[facing=north,half=bottom]
setblock ~11 ~7 ~9 minecraft:cherry_stairs[facing=north,half=bottom]
setblock ~-1 ~8 ~2 minecraft:cherry_stairs[facing=south,half=bottom]
setblock ~0 ~8 ~2 minecraft:cherry_stairs[facing=south,half=bottom]
setblock ~1 ~8 ~2 minecraft:cherry_stairs[facing=south,half=bottom]
setblock ~2 ~8 ~2 minecraft:cherry_stairs[facing=south,half=bottom]
setblock ~3 ~8 ~2 minecraft:cherry_stairs[facing=south,half=bottom]
fill ~4 ~8 ~2 ~6 ~8 ~2 minecraft:glass
setblock ~7 ~8 ~2 minecraft:cherry_stairs[facing=south,half=bottom]
setblock ~8 ~8 ~2 minecraft:cherry_stairs[facing=south,half=bottom]
setblock ~9 ~8 ~2 minecraft:cherry_stairs[facing=south,half=bottom]
setblock ~10 ~8 ~2 minecraft:cherry_stairs[facing=south,half=bottom]
setblock ~11 ~8 ~2 minecraft:cherry_stairs[facing=south,half=bottom]
setblock ~0 ~8 ~3 minecraft:stripped_dark_oak_log[axis=y]
setblock ~10 ~8 ~3 minecraft:stripped_dark_oak_log[axis=y]
setblock ~0 ~8 ~4 minecraft:glass_pane[north=true,east=false,south=true,west=false,waterlogged=false]
setblock ~10 ~8 ~4 minecraft:glass_pane[north=true,east=false,south=true,west=false,waterlogged=false]
setblock ~0 ~8 ~5 minecraft:glass_pane[north=true,east=false,south=true,west=false,waterlogged=false]
setblock ~5 ~8 ~5 minecraft:cherry_log[axis=y]
setblock ~10 ~8 ~5 minecraft:stripped_dark_oak_log[axis=y]
setblock ~0 ~8 ~6 minecraft:glass_pane[north=true,east=false,south=true,west=false,waterlogged=false]
setblock ~10 ~8 ~6 minecraft:glass_pane[north=true,east=false,south=true,west=false,waterlogged=false]
setblock ~0 ~8 ~7 minecraft:stripped_dark_oak_log[axis=y]
setblock ~10 ~8 ~7 minecraft:stripped_dark_oak_log[axis=y]
setblock ~-1 ~8 ~8 minecraft:cherry_stairs[facing=north,half=bottom]
setblock ~0 ~8 ~8 minecraft:cherry_stairs[facing=north,half=bottom]
setblock ~1 ~8 ~8 minecraft:cherry_stairs[facing=north,half=bottom]
setblock ~2 ~8 ~8 minecraft:cherry_stairs[facing=north,half=bottom]
setblock ~3 ~8 ~8 minecraft:cherry_stairs[facing=north,half=bottom]
fill ~4 ~8 ~8 ~6 ~8 ~8 minecraft:glass
setblock ~7 ~8 ~8 minecraft:cherry_stairs[facing=north,half=bottom]
setblock ~8 ~8 ~8 minecraft:cherry_stairs[facing=north,half=bottom]
setblock ~9 ~8 ~8 minecraft:cherry_stairs[facing=north,half=bottom]
setblock ~10 ~8 ~8 minecraft:cherry_stairs[facing=north,half=bottom]
setblock ~11 ~8 ~8 minecraft:cherry_stairs[facing=north,half=bottom]
setblock ~-1 ~9 ~3 minecraft:cherry_stairs[facing=south,half=bottom]
setblock ~0 ~9 ~3 minecraft:cherry_stairs[facing=south,half=bottom]
setblock ~1 ~9 ~3 minecraft:cherry_stairs[facing=south,half=bottom]
setblock ~2 ~9 ~3 minecraft:cherry_stairs[facing=south,half=bottom]
setblock ~3 ~9 ~3 minecraft:cherry_stairs[facing=south,half=bottom]
fill ~4 ~9 ~3 ~6 ~9 ~3 minecraft:glass
setblock ~7 ~9 ~3 minecraft:cherry_stairs[facing=south,half=bottom]
setblock ~8 ~9 ~3 minecraft:cherry_stairs[facing=south,half=bottom]
setblock ~9 ~9 ~3 minecraft:cherry_stairs[facing=south,half=bottom]
setblock ~10 ~9 ~3 minecraft:cherry_stairs[facing=south,half=bottom]
setblock ~11 ~9 ~3 minecraft:cherry_stairs[facing=south,half=bottom]
setblock ~0 ~9 ~4 minecraft:calcite
setblock ~10 ~9 ~4 minecraft:glass_pane[north=false,east=false,south=true,west=false,waterlogged=false]
setblock ~0 ~9 ~5 minecraft:calcite
setblock ~5 ~9 ~5 minecraft:cherry_log[axis=y]
setblock ~10 ~9 ~5 minecraft:stripped_dark_oak_log[axis=y]
setblock ~0 ~9 ~6 minecraft:calcite
setblock ~10 ~9 ~6 minecraft:glass_pane[north=true,east=false,south=false,west=false,waterlogged=false]
setblock ~-1 ~9 ~7 minecraft:cherry_stairs[facing=north,half=bottom]
setblock ~0 ~9 ~7 minecraft:cherry_stairs[facing=north,half=bottom]
setblock ~1 ~9 ~7 minecraft:cherry_stairs[facing=north,half=bottom]
setblock ~2 ~9 ~7 minecraft:cherry_stairs[facing=north,half=bottom]
setblock ~3 ~9 ~7 minecraft:cherry_stairs[facing=north,half=bottom]
fill ~4 ~9 ~7 ~6 ~9 ~7 minecraft:glass
setblock ~7 ~9 ~7 minecraft:cherry_stairs[facing=north,half=bottom]
setblock ~8 ~9 ~7 minecraft:cherry_stairs[facing=north,half=bottom]
setblock ~9 ~9 ~7 minecraft:cherry_stairs[facing=north,half=bottom]
setblock ~10 ~9 ~7 minecraft:cherry_stairs[facing=north,half=bottom]
setblock ~11 ~9 ~7 minecraft:cherry_stairs[facing=north,half=bottom]
setblock ~-1 ~10 ~4 minecraft:cherry_stairs[facing=south,half=bottom]
setblock ~0 ~10 ~4 minecraft:cherry_stairs[facing=south,half=bottom]
setblock ~1 ~10 ~4 minecraft:cherry_stairs[facing=south,half=bottom]
setblock ~2 ~10 ~4 minecraft:cherry_stairs[facing=south,half=bottom]
setblock ~3 ~10 ~4 minecraft:cherry_stairs[facing=south,half=bottom]
fill ~4 ~10 ~4 ~6 ~10 ~4 minecraft:glass
setblock ~7 ~10 ~4 minecraft:cherry_stairs[facing=south,half=bottom]
setblock ~8 ~10 ~4 minecraft:cherry_stairs[facing=south,half=bottom]
setblock ~9 ~10 ~4 minecraft:cherry_stairs[facing=south,half=bottom]
setblock ~10 ~10 ~4 minecraft:cherry_stairs[facing=south,half=bottom]
setblock ~11 ~10 ~4 minecraft:cherry_stairs[facing=south,half=bottom]
fill ~-1 ~10 ~5 ~3 ~10 ~5 minecraft:cherry_planks
setblock ~4 ~10 ~5 minecraft:glass
setblock ~5 ~10 ~5 minecraft:cherry_log[axis=y]
setblock ~6 ~10 ~5 minecraft:glass
fill ~7 ~10 ~5 ~11 ~10 ~5 minecraft:cherry_planks
setblock ~-1 ~10 ~6 minecraft:cherry_stairs[facing=north,half=bottom]
setblock ~0 ~10 ~6 minecraft:cherry_stairs[facing=north,half=bottom]
setblock ~1 ~10 ~6 minecraft:cherry_stairs[facing=north,half=bottom]
setblock ~2 ~10 ~6 minecraft:cherry_stairs[facing=north,half=bottom]
setblock ~3 ~10 ~6 minecraft:cherry_stairs[facing=north,half=bottom]
fill ~4 ~10 ~6 ~6 ~10 ~6 minecraft:glass
setblock ~7 ~10 ~6 minecraft:cherry_stairs[facing=north,half=bottom]
setblock ~8 ~10 ~6 minecraft:cherry_stairs[facing=north,half=bottom]
setblock ~9 ~10 ~6 minecraft:cherry_stairs[facing=north,half=bottom]
setblock ~10 ~10 ~6 minecraft:cherry_stairs[facing=north,half=bottom]
setblock ~11 ~10 ~6 minecraft:cherry_stairs[facing=north,half=bottom]
setblock ~4 ~11 ~1 minecraft:cherry_leaves[persistent=true]
setblock ~6 ~11 ~1 minecraft:cherry_leaves[persistent=true]
setblock ~2 ~11 ~2 minecraft:cherry_leaves[persistent=true]
setblock ~3 ~11 ~2 minecraft:cherry_leaves[persistent=true]
setblock ~4 ~11 ~2 minecraft:cherry_leaves[persistent=true]
setblock ~5 ~11 ~2 minecraft:cherry_leaves[persistent=true]
setblock ~6 ~11 ~2 minecraft:cherry_leaves[persistent=true]
setblock ~7 ~11 ~2 minecraft:cherry_leaves[persistent=true]
setblock ~8 ~11 ~2 minecraft:cherry_leaves[persistent=true]
setblock ~2 ~11 ~3 minecraft:cherry_leaves[persistent=true]
setblock ~3 ~11 ~3 minecraft:cherry_leaves[persistent=true]
setblock ~4 ~11 ~3 minecraft:cherry_leaves[persistent=true]
setblock ~5 ~11 ~3 minecraft:cherry_leaves[persistent=true]
setblock ~6 ~11 ~3 minecraft:cherry_leaves[persistent=true]
setblock ~7 ~11 ~3 minecraft:cherry_leaves[persistent=true]
setblock ~8 ~11 ~3 minecraft:cherry_leaves[persistent=true]
setblock ~1 ~11 ~4 minecraft:cherry_leaves[persistent=true]
setblock ~2 ~11 ~4 minecraft:cherry_leaves[persistent=true]
setblock ~3 ~11 ~4 minecraft:cherry_leaves[persistent=true]
setblock ~4 ~11 ~4 minecraft:cherry_leaves[persistent=true]
setblock ~5 ~11 ~4 minecraft:cherry_leaves[persistent=true]
setblock ~6 ~11 ~4 minecraft:cherry_leaves[persistent=true]
setblock ~7 ~11 ~4 minecraft:cherry_leaves[persistent=true]
setblock ~8 ~11 ~4 minecraft:cherry_leaves[persistent=true]
setblock ~9 ~11 ~4 minecraft:cherry_leaves[persistent=true]
setblock ~-1 ~11 ~5 minecraft:cherry_slab[type=bottom]
setblock ~0 ~11 ~5 minecraft:cherry_slab[type=bottom]
setblock ~1 ~11 ~5 minecraft:cherry_slab[type=bottom]
setblock ~2 ~11 ~5 minecraft:cherry_slab[type=bottom]
setblock ~3 ~11 ~5 minecraft:cherry_slab[type=bottom]
setblock ~4 ~11 ~5 minecraft:glass
setblock ~5 ~11 ~5 minecraft:cherry_log[axis=y]
setblock ~6 ~11 ~5 minecraft:glass
setblock ~7 ~11 ~5 minecraft:cherry_slab[type=bottom]
setblock ~8 ~11 ~5 minecraft:cherry_slab[type=bottom]
setblock ~9 ~11 ~5 minecraft:cherry_slab[type=bottom]
setblock ~10 ~11 ~5 minecraft:cherry_slab[type=bottom]
setblock ~11 ~11 ~5 minecraft:cherry_slab[type=bottom]
setblock ~1 ~11 ~6 minecraft:cherry_leaves[persistent=true]
setblock ~3 ~11 ~6 minecraft:cherry_leaves[persistent=true]
setblock ~4 ~11 ~6 minecraft:cherry_leaves[persistent=true]
setblock ~5 ~11 ~6 minecraft:cherry_leaves[persistent=true]
setblock ~6 ~11 ~6 minecraft:cherry_leaves[persistent=true]
setblock ~7 ~11 ~6 minecraft:cherry_leaves[persistent=true]
setblock ~9 ~11 ~6 minecraft:cherry_leaves[persistent=true]
setblock ~2 ~11 ~7 minecraft:cherry_leaves[persistent=true]
setblock ~3 ~11 ~7 minecraft:cherry_leaves[persistent=true]
setblock ~4 ~11 ~7 minecraft:cherry_leaves[persistent=true]
setblock ~5 ~11 ~7 minecraft:cherry_leaves[persistent=true]
setblock ~6 ~11 ~7 minecraft:cherry_leaves[persistent=true]
setblock ~7 ~11 ~7 minecraft:cherry_leaves[persistent=true]
setblock ~8 ~11 ~7 minecraft:cherry_leaves[persistent=true]
setblock ~2 ~11 ~8 minecraft:cherry_leaves[persistent=true]
setblock ~3 ~11 ~8 minecraft:cherry_leaves[persistent=true]
setblock ~4 ~11 ~8 minecraft:cherry_leaves[persistent=true]
setblock ~5 ~11 ~8 minecraft:cherry_leaves[persistent=true]
setblock ~6 ~11 ~8 minecraft:cherry_leaves[persistent=true]
setblock ~7 ~11 ~8 minecraft:cherry_leaves[persistent=true]
setblock ~8 ~11 ~8 minecraft:cherry_leaves[persistent=true]
setblock ~4 ~11 ~9 minecraft:cherry_leaves[persistent=true]
setblock ~4 ~12 ~0 minecraft:cherry_leaves[persistent=true]
setblock ~5 ~12 ~0 minecraft:cherry_leaves[persistent=true]
setblock ~6 ~12 ~0 minecraft:cherry_leaves[persistent=true]
setblock ~3 ~12 ~1 minecraft:cherry_leaves[persistent=true]
setblock ~4 ~12 ~1 minecraft:cherry_leaves[persistent=true]
setblock ~5 ~12 ~1 minecraft:cherry_leaves[persistent=true]
setblock ~6 ~12 ~1 minecraft:cherry_leaves[persistent=true]
setblock ~1 ~12 ~2 minecraft:cherry_leaves[persistent=true]
setblock ~2 ~12 ~2 minecraft:cherry_leaves[persistent=true]
setblock ~3 ~12 ~2 minecraft:cherry_leaves[persistent=true]
setblock ~4 ~12 ~2 minecraft:cherry_leaves[persistent=true]
setblock ~5 ~12 ~2 minecraft:cherry_leaves[persistent=true]
setblock ~6 ~12 ~2 minecraft:cherry_leaves[persistent=true]
setblock ~7 ~12 ~2 minecraft:cherry_leaves[persistent=true]
setblock ~8 ~12 ~2 minecraft:cherry_leaves[persistent=true]
setblock ~9 ~12 ~2 minecraft:cherry_leaves[persistent=true]
setblock ~1 ~12 ~3 minecraft:cherry_leaves[persistent=true]
setblock ~2 ~12 ~3 minecraft:cherry_leaves[persistent=true]
setblock ~3 ~12 ~3 minecraft:cherry_leaves[persistent=true]
setblock ~4 ~12 ~3 minecraft:cherry_leaves[persistent=true]
setblock ~5 ~12 ~3 minecraft:cherry_leaves[persistent=true]
setblock ~6 ~12 ~3 minecraft:cherry_leaves[persistent=true]
setblock ~7 ~12 ~3 minecraft:cherry_leaves[persistent=true]
setblock ~8 ~12 ~3 minecraft:cherry_leaves[persistent=true]
setblock ~9 ~12 ~3 minecraft:cherry_leaves[persistent=true]
setblock ~1 ~12 ~4 minecraft:cherry_leaves[persistent=true]
setblock ~2 ~12 ~4 minecraft:cherry_leaves[persistent=true]
setblock ~3 ~12 ~4 minecraft:cherry_leaves[persistent=true]
setblock ~4 ~12 ~4 minecraft:cherry_leaves[persistent=true]
setblock ~5 ~12 ~4 minecraft:cherry_log[axis=y]
setblock ~6 ~12 ~4 minecraft:cherry_leaves[persistent=true]
setblock ~7 ~12 ~4 minecraft:cherry_leaves[persistent=true]
setblock ~8 ~12 ~4 minecraft:cherry_leaves[persistent=true]
setblock ~9 ~12 ~4 minecraft:cherry_leaves[persistent=true]
setblock ~10 ~12 ~4 minecraft:cherry_leaves[persistent=true]
setblock ~1 ~12 ~5 minecraft:cherry_leaves[persistent=true]
setblock ~2 ~12 ~5 minecraft:cherry_leaves[persistent=true]
setblock ~3 ~12 ~5 minecraft:cherry_leaves[persistent=true]
setblock ~4 ~12 ~5 minecraft:cherry_log[axis=y]
setblock ~5 ~12 ~5 minecraft:cherry_log[axis=y]
setblock ~6 ~12 ~5 minecraft:cherry_log[axis=y]
setblock ~7 ~12 ~5 minecraft:cherry_leaves[persistent=true]
setblock ~8 ~12 ~5 minecraft:cherry_leaves[persistent=true]
setblock ~9 ~12 ~5 minecraft:cherry_leaves[persistent=true]
setblock ~10 ~12 ~5 minecraft:cherry_leaves[persistent=true]
setblock ~0 ~12 ~6 minecraft:cherry_leaves[persistent=true]
setblock ~1 ~12 ~6 minecraft:cherry_leaves[persistent=true]
setblock ~2 ~12 ~6 minecraft:cherry_leaves[persistent=true]
setblock ~3 ~12 ~6 minecraft:cherry_leaves[persistent=true]
setblock ~4 ~12 ~6 minecraft:cherry_leaves[persistent=true]
setblock ~5 ~12 ~6 minecraft:cherry_log[axis=y]
setblock ~6 ~12 ~6 minecraft:cherry_leaves[persistent=true]
setblock ~7 ~12 ~6 minecraft:cherry_leaves[persistent=true]
setblock ~8 ~12 ~6 minecraft:cherry_leaves[persistent=true]
setblock ~9 ~12 ~6 minecraft:cherry_leaves[persistent=true]
setblock ~10 ~12 ~6 minecraft:cherry_leaves[persistent=true]
setblock ~1 ~12 ~7 minecraft:cherry_leaves[persistent=true]
setblock ~2 ~12 ~7 minecraft:cherry_leaves[persistent=true]
setblock ~3 ~12 ~7 minecraft:cherry_leaves[persistent=true]
setblock ~4 ~12 ~7 minecraft:cherry_leaves[persistent=true]
setblock ~5 ~12 ~7 minecraft:cherry_leaves[persistent=true]
setblock ~6 ~12 ~7 minecraft:cherry_leaves[persistent=true]
setblock ~7 ~12 ~7 minecraft:cherry_leaves[persistent=true]
setblock ~8 ~12 ~7 minecraft:cherry_leaves[persistent=true]
setblock ~9 ~12 ~7 minecraft:cherry_leaves[persistent=true]
setblock ~1 ~12 ~8 minecraft:cherry_leaves[persistent=true]
setblock ~2 ~12 ~8 minecraft:cherry_leaves[persistent=true]
setblock ~3 ~12 ~8 minecraft:cherry_leaves[persistent=true]
setblock ~4 ~12 ~8 minecraft:cherry_leaves[persistent=true]
setblock ~5 ~12 ~8 minecraft:cherry_leaves[persistent=true]
setblock ~6 ~12 ~8 minecraft:cherry_leaves[persistent=true]
setblock ~7 ~12 ~8 minecraft:cherry_leaves[persistent=true]
setblock ~8 ~12 ~8 minecraft:cherry_leaves[persistent=true]
setblock ~9 ~12 ~8 minecraft:cherry_leaves[persistent=true]
setblock ~2 ~12 ~9 minecraft:cherry_leaves[persistent=true]
setblock ~3 ~12 ~9 minecraft:cherry_leaves[persistent=true]
setblock ~4 ~12 ~9 minecraft:cherry_leaves[persistent=true]
setblock ~5 ~12 ~9 minecraft:cherry_leaves[persistent=true]
setblock ~6 ~12 ~9 minecraft:cherry_leaves[persistent=true]
setblock ~7 ~12 ~9 minecraft:cherry_leaves[persistent=true]
setblock ~8 ~12 ~9 minecraft:cherry_leaves[persistent=true]
setblock ~4 ~12 ~10 minecraft:cherry_leaves[persistent=true]
setblock ~5 ~12 ~10 minecraft:cherry_leaves[persistent=true]
setblock ~6 ~12 ~10 minecraft:cherry_leaves[persistent=true]
setblock ~3 ~13 ~0 minecraft:cherry_leaves[persistent=true]
setblock ~4 ~13 ~0 minecraft:cherry_leaves[persistent=true]
setblock ~5 ~13 ~0 minecraft:cherry_leaves[persistent=true]
setblock ~6 ~13 ~0 minecraft:cherry_leaves[persistent=true]
setblock ~7 ~13 ~0 minecraft:cherry_leaves[persistent=true]
setblock ~2 ~13 ~1 minecraft:cherry_leaves[persistent=true]
setblock ~3 ~13 ~1 minecraft:cherry_leaves[persistent=true]
setblock ~4 ~13 ~1 minecraft:cherry_leaves[persistent=true]
setblock ~5 ~13 ~1 minecraft:cherry_leaves[persistent=true]
setblock ~6 ~13 ~1 minecraft:cherry_leaves[persistent=true]
setblock ~7 ~13 ~1 minecraft:cherry_leaves[persistent=true]
setblock ~8 ~13 ~1 minecraft:cherry_leaves[persistent=true]
setblock ~1 ~13 ~2 minecraft:cherry_leaves[persistent=true]
setblock ~2 ~13 ~2 minecraft:cherry_leaves[persistent=true]
setblock ~3 ~13 ~2 minecraft:cherry_leaves[persistent=true]
setblock ~4 ~13 ~2 minecraft:cherry_leaves[persistent=true]
setblock ~5 ~13 ~2 minecraft:cherry_leaves[persistent=true]
setblock ~6 ~13 ~2 minecraft:cherry_leaves[persistent=true]
setblock ~7 ~13 ~2 minecraft:cherry_leaves[persistent=true]
setblock ~8 ~13 ~2 minecraft:cherry_leaves[persistent=true]
setblock ~9 ~13 ~2 minecraft:cherry_leaves[persistent=true]
setblock ~0 ~13 ~3 minecraft:cherry_leaves[persistent=true]
setblock ~1 ~13 ~3 minecraft:cherry_leaves[persistent=true]
setblock ~2 ~13 ~3 minecraft:cherry_leaves[persistent=true]
setblock ~3 ~13 ~3 minecraft:cherry_leaves[persistent=true]
setblock ~4 ~13 ~3 minecraft:cherry_leaves[persistent=true]
setblock ~5 ~13 ~3 minecraft:cherry_log[axis=y]
setblock ~6 ~13 ~3 minecraft:cherry_leaves[persistent=true]
setblock ~7 ~13 ~3 minecraft:cherry_leaves[persistent=true]
setblock ~8 ~13 ~3 minecraft:cherry_leaves[persistent=true]
setblock ~9 ~13 ~3 minecraft:cherry_leaves[persistent=true]
setblock ~10 ~13 ~3 minecraft:cherry_leaves[persistent=true]
setblock ~0 ~13 ~4 minecraft:cherry_leaves[persistent=true]
setblock ~1 ~13 ~4 minecraft:cherry_leaves[persistent=true]
setblock ~2 ~13 ~4 minecraft:cherry_leaves[persistent=true]
setblock ~3 ~13 ~4 minecraft:cherry_leaves[persistent=true]
setblock ~4 ~13 ~4 minecraft:cherry_leaves[persistent=true]
setblock ~5 ~13 ~4 minecraft:cherry_leaves[persistent=true]
setblock ~6 ~13 ~4 minecraft:cherry_leaves[persistent=true]
setblock ~7 ~13 ~4 minecraft:cherry_leaves[persistent=true]
setblock ~8 ~13 ~4 minecraft:cherry_leaves[persistent=true]
setblock ~9 ~13 ~4 minecraft:cherry_leaves[persistent=true]
setblock ~10 ~13 ~4 minecraft:cherry_leaves[persistent=true]
setblock ~0 ~13 ~5 minecraft:cherry_leaves[persistent=true]
setblock ~1 ~13 ~5 minecraft:cherry_leaves[persistent=true]
setblock ~2 ~13 ~5 minecraft:cherry_leaves[persistent=true]
setblock ~3 ~13 ~5 minecraft:cherry_log[axis=y]
setblock ~4 ~13 ~5 minecraft:cherry_leaves[persistent=true]
setblock ~5 ~13 ~5 minecraft:cherry_log[axis=y]
setblock ~6 ~13 ~5 minecraft:cherry_leaves[persistent=true]
setblock ~7 ~13 ~5 minecraft:cherry_log[axis=y]
setblock ~8 ~13 ~5 minecraft:cherry_leaves[persistent=true]
setblock ~9 ~13 ~5 minecraft:cherry_leaves[persistent=true]
setblock ~10 ~13 ~5 minecraft:cherry_leaves[persistent=true]
setblock ~0 ~13 ~6 minecraft:cherry_leaves[persistent=true]
setblock ~1 ~13 ~6 minecraft:cherry_leaves[persistent=true]
setblock ~2 ~13 ~6 minecraft:cherry_leaves[persistent=true]
setblock ~3 ~13 ~6 minecraft:cherry_leaves[persistent=true]
setblock ~4 ~13 ~6 minecraft:cherry_leaves[persistent=true]
setblock ~5 ~13 ~6 minecraft:cherry_leaves[persistent=true]
setblock ~6 ~13 ~6 minecraft:cherry_leaves[persistent=true]
setblock ~7 ~13 ~6 minecraft:cherry_leaves[persistent=true]
setblock ~8 ~13 ~6 minecraft:cherry_leaves[persistent=true]
setblock ~9 ~13 ~6 minecraft:cherry_leaves[persistent=true]
setblock ~10 ~13 ~6 minecraft:cherry_leaves[persistent=true]
setblock ~0 ~13 ~7 minecraft:cherry_leaves[persistent=true]
setblock ~1 ~13 ~7 minecraft:cherry_leaves[persistent=true]
setblock ~2 ~13 ~7 minecraft:cherry_leaves[persistent=true]
setblock ~3 ~13 ~7 minecraft:cherry_leaves[persistent=true]
setblock ~4 ~13 ~7 minecraft:cherry_leaves[persistent=true]
setblock ~5 ~13 ~7 minecraft:cherry_log[axis=y]
setblock ~6 ~13 ~7 minecraft:cherry_leaves[persistent=true]
setblock ~7 ~13 ~7 minecraft:cherry_leaves[persistent=true]
setblock ~8 ~13 ~7 minecraft:cherry_leaves[persistent=true]
setblock ~9 ~13 ~7 minecraft:cherry_leaves[persistent=true]
setblock ~10 ~13 ~7 minecraft:cherry_leaves[persistent=true]
setblock ~1 ~13 ~8 minecraft:cherry_leaves[persistent=true]
setblock ~2 ~13 ~8 minecraft:cherry_leaves[persistent=true]
setblock ~3 ~13 ~8 minecraft:cherry_leaves[persistent=true]
setblock ~4 ~13 ~8 minecraft:cherry_leaves[persistent=true]
setblock ~5 ~13 ~8 minecraft:cherry_leaves[persistent=true]
setblock ~6 ~13 ~8 minecraft:cherry_leaves[persistent=true]
setblock ~7 ~13 ~8 minecraft:cherry_leaves[persistent=true]
setblock ~8 ~13 ~8 minecraft:cherry_leaves[persistent=true]
setblock ~9 ~13 ~8 minecraft:cherry_leaves[persistent=true]
setblock ~2 ~13 ~9 minecraft:cherry_leaves[persistent=true]
setblock ~3 ~13 ~9 minecraft:cherry_leaves[persistent=true]
setblock ~4 ~13 ~9 minecraft:cherry_leaves[persistent=true]
setblock ~5 ~13 ~9 minecraft:cherry_leaves[persistent=true]
setblock ~6 ~13 ~9 minecraft:cherry_leaves[persistent=true]
setblock ~7 ~13 ~9 minecraft:cherry_leaves[persistent=true]
setblock ~8 ~13 ~9 minecraft:cherry_leaves[persistent=true]
setblock ~3 ~13 ~10 minecraft:cherry_leaves[persistent=true]
setblock ~4 ~13 ~10 minecraft:cherry_leaves[persistent=true]
setblock ~5 ~13 ~10 minecraft:cherry_leaves[persistent=true]
setblock ~6 ~13 ~10 minecraft:cherry_leaves[persistent=true]
setblock ~7 ~13 ~10 minecraft:cherry_leaves[persistent=true]
setblock ~3 ~14 ~0 minecraft:cherry_leaves[persistent=true]
setblock ~4 ~14 ~0 minecraft:cherry_leaves[persistent=true]
setblock ~5 ~14 ~0 minecraft:cherry_leaves[persistent=true]
setblock ~6 ~14 ~0 minecraft:cherry_leaves[persistent=true]
setblock ~7 ~14 ~0 minecraft:cherry_leaves[persistent=true]
setblock ~3 ~14 ~1 minecraft:cherry_leaves[persistent=true]
setblock ~4 ~14 ~1 minecraft:cherry_leaves[persistent=true]
setblock ~5 ~14 ~1 minecraft:cherry_leaves[persistent=true]
setblock ~6 ~14 ~1 minecraft:cherry_leaves[persistent=true]
setblock ~7 ~14 ~1 minecraft:cherry_leaves[persistent=true]
setblock ~2 ~14 ~2 minecraft:cherry_leaves[persistent=true]
setblock ~3 ~14 ~2 minecraft:cherry_leaves[persistent=true]
setblock ~4 ~14 ~2 minecraft:cherry_leaves[persistent=true]
setblock ~5 ~14 ~2 minecraft:cherry_leaves[persistent=true]
setblock ~6 ~14 ~2 minecraft:cherry_leaves[persistent=true]
setblock ~7 ~14 ~2 minecraft:cherry_leaves[persistent=true]
setblock ~8 ~14 ~2 minecraft:cherry_leaves[persistent=true]
setblock ~9 ~14 ~2 minecraft:cherry_leaves[persistent=true]
setblock ~1 ~14 ~3 minecraft:cherry_leaves[persistent=true]
setblock ~2 ~14 ~3 minecraft:cherry_leaves[persistent=true]
setblock ~3 ~14 ~3 minecraft:cherry_leaves[persistent=true]
setblock ~4 ~14 ~3 minecraft:cherry_leaves[persistent=true]
setblock ~5 ~14 ~3 minecraft:cherry_leaves[persistent=true]
setblock ~6 ~14 ~3 minecraft:cherry_leaves[persistent=true]
setblock ~7 ~14 ~3 minecraft:cherry_leaves[persistent=true]
setblock ~8 ~14 ~3 minecraft:cherry_leaves[persistent=true]
setblock ~9 ~14 ~3 minecraft:cherry_leaves[persistent=true]
setblock ~1 ~14 ~4 minecraft:cherry_leaves[persistent=true]
setblock ~2 ~14 ~4 minecraft:cherry_leaves[persistent=true]
setblock ~3 ~14 ~4 minecraft:cherry_leaves[persistent=true]
setblock ~4 ~14 ~4 minecraft:cherry_leaves[persistent=true]
setblock ~5 ~14 ~4 minecraft:cherry_leaves[persistent=true]
setblock ~6 ~14 ~4 minecraft:cherry_leaves[persistent=true]
setblock ~7 ~14 ~4 minecraft:cherry_leaves[persistent=true]
setblock ~8 ~14 ~4 minecraft:cherry_leaves[persistent=true]
setblock ~9 ~14 ~4 minecraft:cherry_leaves[persistent=true]
setblock ~10 ~14 ~4 minecraft:cherry_leaves[persistent=true]
setblock ~1 ~14 ~5 minecraft:cherry_leaves[persistent=true]
setblock ~2 ~14 ~5 minecraft:cherry_leaves[persistent=true]
setblock ~3 ~14 ~5 minecraft:cherry_leaves[persistent=true]
setblock ~4 ~14 ~5 minecraft:cherry_leaves[persistent=true]
setblock ~5 ~14 ~5 minecraft:cherry_leaves[persistent=true]
setblock ~6 ~14 ~5 minecraft:cherry_leaves[persistent=true]
setblock ~7 ~14 ~5 minecraft:cherry_leaves[persistent=true]
setblock ~8 ~14 ~5 minecraft:cherry_leaves[persistent=true]
setblock ~9 ~14 ~5 minecraft:cherry_leaves[persistent=true]
setblock ~10 ~14 ~5 minecraft:cherry_leaves[persistent=true]
setblock ~0 ~14 ~6 minecraft:cherry_leaves[persistent=true]
setblock ~1 ~14 ~6 minecraft:cherry_leaves[persistent=true]
setblock ~2 ~14 ~6 minecraft:cherry_leaves[persistent=true]
setblock ~3 ~14 ~6 minecraft:cherry_leaves[persistent=true]
setblock ~4 ~14 ~6 minecraft:cherry_leaves[persistent=true]
setblock ~5 ~14 ~6 minecraft:cherry_leaves[persistent=true]
setblock ~6 ~14 ~6 minecraft:cherry_leaves[persistent=true]
setblock ~7 ~14 ~6 minecraft:cherry_leaves[persistent=true]
setblock ~8 ~14 ~6 minecraft:cherry_leaves[persistent=true]
setblock ~9 ~14 ~6 minecraft:cherry_leaves[persistent=true]
setblock ~10 ~14 ~6 minecraft:cherry_leaves[persistent=true]
setblock ~0 ~14 ~7 minecraft:cherry_leaves[persistent=true]
setblock ~1 ~14 ~7 minecraft:cherry_leaves[persistent=true]
setblock ~2 ~14 ~7 minecraft:cherry_leaves[persistent=true]
setblock ~3 ~14 ~7 minecraft:cherry_leaves[persistent=true]
setblock ~4 ~14 ~7 minecraft:cherry_leaves[persistent=true]
setblock ~5 ~14 ~7 minecraft:cherry_leaves[persistent=true]
setblock ~6 ~14 ~7 minecraft:cherry_leaves[persistent=true]
setblock ~7 ~14 ~7 minecraft:cherry_leaves[persistent=true]
setblock ~8 ~14 ~7 minecraft:cherry_leaves[persistent=true]
setblock ~9 ~14 ~7 minecraft:cherry_leaves[persistent=true]
setblock ~1 ~14 ~8 minecraft:cherry_leaves[persistent=true]
setblock ~2 ~14 ~8 minecraft:cherry_leaves[persistent=true]
setblock ~3 ~14 ~8 minecraft:cherry_leaves[persistent=true]
setblock ~4 ~14 ~8 minecraft:cherry_leaves[persistent=true]
setblock ~5 ~14 ~8 minecraft:cherry_leaves[persistent=true]
setblock ~6 ~14 ~8 minecraft:cherry_leaves[persistent=true]
setblock ~7 ~14 ~8 minecraft:cherry_leaves[persistent=true]
setblock ~8 ~14 ~8 minecraft:cherry_leaves[persistent=true]
setblock ~9 ~14 ~8 minecraft:cherry_leaves[persistent=true]
setblock ~3 ~14 ~9 minecraft:cherry_leaves[persistent=true]
setblock ~4 ~14 ~9 minecraft:cherry_leaves[persistent=true]
setblock ~5 ~14 ~9 minecraft:cherry_leaves[persistent=true]
setblock ~6 ~14 ~9 minecraft:cherry_leaves[persistent=true]
setblock ~7 ~14 ~9 minecraft:cherry_leaves[persistent=true]
setblock ~8 ~14 ~9 minecraft:cherry_leaves[persistent=true]
setblock ~3 ~14 ~10 minecraft:cherry_leaves[persistent=true]
setblock ~4 ~14 ~10 minecraft:cherry_leaves[persistent=true]
setblock ~5 ~14 ~10 minecraft:cherry_leaves[persistent=true]
setblock ~7 ~14 ~10 minecraft:cherry_leaves[persistent=true]
setblock ~3 ~15 ~1 minecraft:cherry_leaves[persistent=true]
setblock ~4 ~15 ~1 minecraft:cherry_leaves[persistent=true]
setblock ~5 ~15 ~1 minecraft:cherry_leaves[persistent=true]
setblock ~7 ~15 ~1 minecraft:cherry_leaves[persistent=true]
setblock ~3 ~15 ~2 minecraft:cherry_leaves[persistent=true]
setblock ~4 ~15 ~2 minecraft:cherry_leaves[persistent=true]
setblock ~5 ~15 ~2 minecraft:cherry_leaves[persistent=true]
setblock ~6 ~15 ~2 minecraft:cherry_leaves[persistent=true]
setblock ~7 ~15 ~2 minecraft:cherry_leaves[persistent=true]
setblock ~8 ~15 ~2 minecraft:cherry_leaves[persistent=true]
setblock ~1 ~15 ~3 minecraft:cherry_leaves[persistent=true]
setblock ~2 ~15 ~3 minecraft:cherry_leaves[persistent=true]
setblock ~3 ~15 ~3 minecraft:cherry_leaves[persistent=true]
setblock ~4 ~15 ~3 minecraft:cherry_leaves[persistent=true]
setblock ~5 ~15 ~3 minecraft:cherry_leaves[persistent=true]
setblock ~6 ~15 ~3 minecraft:cherry_leaves[persistent=true]
setblock ~7 ~15 ~3 minecraft:cherry_leaves[persistent=true]
setblock ~8 ~15 ~3 minecraft:cherry_leaves[persistent=true]
setblock ~9 ~15 ~3 minecraft:cherry_leaves[persistent=true]
setblock ~1 ~15 ~4 minecraft:cherry_leaves[persistent=true]
setblock ~2 ~15 ~4 minecraft:cherry_leaves[persistent=true]
setblock ~3 ~15 ~4 minecraft:cherry_leaves[persistent=true]
setblock ~4 ~15 ~4 minecraft:cherry_leaves[persistent=true]
setblock ~5 ~15 ~4 minecraft:cherry_leaves[persistent=true]
setblock ~6 ~15 ~4 minecraft:cherry_leaves[persistent=true]
setblock ~7 ~15 ~4 minecraft:cherry_leaves[persistent=true]
setblock ~8 ~15 ~4 minecraft:cherry_leaves[persistent=true]
setblock ~2 ~15 ~5 minecraft:cherry_leaves[persistent=true]
setblock ~3 ~15 ~5 minecraft:cherry_leaves[persistent=true]
setblock ~4 ~15 ~5 minecraft:cherry_leaves[persistent=true]
setblock ~5 ~15 ~5 minecraft:cherry_leaves[persistent=true]
setblock ~6 ~15 ~5 minecraft:cherry_leaves[persistent=true]
setblock ~7 ~15 ~5 minecraft:cherry_leaves[persistent=true]
setblock ~8 ~15 ~5 minecraft:cherry_leaves[persistent=true]
setblock ~9 ~15 ~5 minecraft:cherry_leaves[persistent=true]
setblock ~1 ~15 ~6 minecraft:cherry_leaves[persistent=true]
setblock ~2 ~15 ~6 minecraft:cherry_leaves[persistent=true]
setblock ~3 ~15 ~6 minecraft:cherry_leaves[persistent=true]
setblock ~4 ~15 ~6 minecraft:cherry_leaves[persistent=true]
setblock ~5 ~15 ~6 minecraft:cherry_leaves[persistent=true]
setblock ~6 ~15 ~6 minecraft:cherry_leaves[persistent=true]
setblock ~7 ~15 ~6 minecraft:cherry_leaves[persistent=true]
setblock ~8 ~15 ~6 minecraft:cherry_leaves[persistent=true]
setblock ~9 ~15 ~6 minecraft:cherry_leaves[persistent=true]
setblock ~1 ~15 ~7 minecraft:cherry_leaves[persistent=true]
setblock ~2 ~15 ~7 minecraft:cherry_leaves[persistent=true]
setblock ~3 ~15 ~7 minecraft:cherry_leaves[persistent=true]
setblock ~4 ~15 ~7 minecraft:cherry_leaves[persistent=true]
setblock ~5 ~15 ~7 minecraft:cherry_leaves[persistent=true]
setblock ~6 ~15 ~7 minecraft:cherry_leaves[persistent=true]
setblock ~7 ~15 ~7 minecraft:cherry_leaves[persistent=true]
setblock ~8 ~15 ~7 minecraft:cherry_leaves[persistent=true]
setblock ~9 ~15 ~7 minecraft:cherry_leaves[persistent=true]
setblock ~2 ~15 ~8 minecraft:cherry_leaves[persistent=true]
setblock ~3 ~15 ~8 minecraft:cherry_leaves[persistent=true]
setblock ~4 ~15 ~8 minecraft:cherry_leaves[persistent=true]
setblock ~5 ~15 ~8 minecraft:cherry_leaves[persistent=true]
setblock ~6 ~15 ~8 minecraft:cherry_leaves[persistent=true]
setblock ~7 ~15 ~8 minecraft:cherry_leaves[persistent=true]
setblock ~8 ~15 ~8 minecraft:cherry_leaves[persistent=true]
setblock ~3 ~15 ~9 minecraft:cherry_leaves[persistent=true]
setblock ~4 ~15 ~9 minecraft:cherry_leaves[persistent=true]
setblock ~5 ~15 ~9 minecraft:cherry_leaves[persistent=true]
setblock ~6 ~15 ~9 minecraft:cherry_leaves[persistent=true]
setblock ~4 ~16 ~2 minecraft:cherry_leaves[persistent=true]
setblock ~5 ~16 ~2 minecraft:cherry_leaves[persistent=true]
setblock ~6 ~16 ~2 minecraft:cherry_leaves[persistent=true]
setblock ~3 ~16 ~3 minecraft:cherry_leaves[persistent=true]
setblock ~6 ~16 ~3 minecraft:cherry_leaves[persistent=true]
setblock ~7 ~16 ~3 minecraft:cherry_leaves[persistent=true]
setblock ~2 ~16 ~4 minecraft:cherry_leaves[persistent=true]
setblock ~5 ~16 ~4 minecraft:cherry_leaves[persistent=true]
setblock ~6 ~16 ~4 minecraft:cherry_leaves[persistent=true]
setblock ~7 ~16 ~4 minecraft:cherry_leaves[persistent=true]
setblock ~8 ~16 ~4 minecraft:cherry_leaves[persistent=true]
setblock ~2 ~16 ~5 minecraft:cherry_leaves[persistent=true]
setblock ~3 ~16 ~5 minecraft:cherry_leaves[persistent=true]
setblock ~4 ~16 ~5 minecraft:cherry_leaves[persistent=true]
setblock ~5 ~16 ~5 minecraft:cherry_leaves[persistent=true]
setblock ~6 ~16 ~5 minecraft:cherry_leaves[persistent=true]
setblock ~8 ~16 ~5 minecraft:cherry_leaves[persistent=true]
setblock ~2 ~16 ~6 minecraft:cherry_leaves[persistent=true]
setblock ~3 ~16 ~6 minecraft:cherry_leaves[persistent=true]
setblock ~4 ~16 ~6 minecraft:cherry_leaves[persistent=true]
setblock ~5 ~16 ~6 minecraft:cherry_leaves[persistent=true]
setblock ~6 ~16 ~6 minecraft:cherry_leaves[persistent=true]
setblock ~7 ~16 ~6 minecraft:cherry_leaves[persistent=true]
setblock ~8 ~16 ~6 minecraft:cherry_leaves[persistent=true]
setblock ~3 ~16 ~7 minecraft:cherry_leaves[persistent=true]
setblock ~4 ~16 ~7 minecraft:cherry_leaves[persistent=true]
setblock ~5 ~16 ~7 minecraft:cherry_leaves[persistent=true]
setblock ~6 ~16 ~7 minecraft:cherry_leaves[persistent=true]
setblock ~5 ~16 ~8 minecraft:cherry_leaves[persistent=true]
setblock ~6 ~16 ~8 minecraft:cherry_leaves[persistent=true]
setblock ~5 ~-1 ~-3 minecraft:gravel
setblock ~4 ~-1 ~-2 minecraft:gravel
setblock ~6 ~-1 ~-2 minecraft:gravel
setblock ~-3 ~0 ~-3 minecraft:pink_petals[flower_amount=2,facing=north]
setblock ~0 ~0 ~-3 minecraft:flowering_azalea
setblock ~1 ~0 ~-3 minecraft:azure_bluet
setblock ~8 ~0 ~-3 minecraft:allium
setblock ~9 ~0 ~-3 minecraft:fern
setblock ~10 ~0 ~-3 minecraft:lily_of_the_valley
setblock ~12 ~0 ~-3 minecraft:flowering_azalea
setblock ~-3 ~0 ~-2 minecraft:pink_tulip
setblock ~0 ~0 ~-2 minecraft:short_grass
setblock ~1 ~0 ~-2 minecraft:flowering_azalea
setblock ~2 ~0 ~-2 minecraft:pink_petals[flower_amount=4,facing=north]
setblock ~3 ~0 ~-2 minecraft:pink_petals[flower_amount=3,facing=north]
setblock ~7 ~0 ~-2 minecraft:pink_petals[flower_amount=3,facing=north]
setblock ~8 ~0 ~-2 minecraft:fern
setblock ~10 ~0 ~-2 minecraft:azure_bluet
setblock ~-3 ~0 ~-1 minecraft:flowering_azalea
setblock ~-1 ~0 ~-1 minecraft:pink_petals[flower_amount=2,facing=north]
setblock ~2 ~0 ~-1 minecraft:flowering_azalea
setblock ~3 ~0 ~-1 minecraft:flowering_azalea
setblock ~8 ~0 ~-1 minecraft:flowering_azalea
setblock ~9 ~0 ~-1 minecraft:pink_petals[flower_amount=4,facing=north]
setblock ~11 ~0 ~-1 minecraft:pink_petals[flower_amount=2,facing=north]
setblock ~12 ~0 ~-1 minecraft:lily_of_the_valley
setblock ~-2 ~0 ~0 minecraft:pink_petals[flower_amount=2,facing=north]
setblock ~-1 ~0 ~0 minecraft:short_grass
setblock ~11 ~0 ~0 minecraft:pink_tulip
setblock ~12 ~0 ~0 minecraft:flowering_azalea
setblock ~13 ~0 ~0 minecraft:pink_petals[flower_amount=3,facing=north]
setblock ~-3 ~0 ~1 minecraft:flowering_azalea
setblock ~-2 ~0 ~1 minecraft:pink_petals[flower_amount=3,facing=north]
setblock ~12 ~0 ~1 minecraft:allium
setblock ~13 ~0 ~1 minecraft:pink_petals[flower_amount=2,facing=north]
setblock ~-3 ~0 ~2 minecraft:azure_bluet
setblock ~-2 ~0 ~2 minecraft:pink_petals[flower_amount=4,facing=north]
setblock ~12 ~0 ~2 minecraft:short_grass
setblock ~13 ~0 ~2 minecraft:pink_petals[flower_amount=1,facing=north]
setblock ~-1 ~0 ~3 minecraft:azure_bluet
setblock ~11 ~0 ~3 minecraft:pink_petals[flower_amount=2,facing=north]
setblock ~13 ~0 ~3 minecraft:pink_petals[flower_amount=4,facing=north]
setblock ~-3 ~0 ~4 minecraft:lily_of_the_valley
setblock ~-2 ~0 ~4 minecraft:pink_tulip
setblock ~-1 ~0 ~4 minecraft:cornflower
setblock ~12 ~0 ~4 minecraft:pink_petals[flower_amount=4,facing=north]
setblock ~13 ~0 ~4 minecraft:azure_bluet
setblock ~-2 ~0 ~5 minecraft:short_grass
setblock ~-1 ~0 ~5 minecraft:flowering_azalea
setblock ~13 ~0 ~5 minecraft:pink_petals[flower_amount=2,facing=north]
setblock ~-3 ~0 ~6 minecraft:pink_petals[flower_amount=1,facing=north]
setblock ~11 ~0 ~6 minecraft:flowering_azalea
setblock ~13 ~0 ~6 minecraft:pink_petals[flower_amount=1,facing=north]
setblock ~-3 ~0 ~7 minecraft:flowering_azalea
setblock ~-1 ~0 ~7 minecraft:lily_of_the_valley
setblock ~12 ~0 ~7 minecraft:lily_of_the_valley
setblock ~13 ~0 ~7 minecraft:cornflower
setblock ~-3 ~0 ~8 minecraft:pink_petals[flower_amount=3,facing=north]
setblock ~-1 ~0 ~8 minecraft:flowering_azalea
setblock ~11 ~0 ~8 minecraft:pink_tulip
setblock ~13 ~0 ~8 minecraft:azure_bluet
setblock ~-3 ~0 ~9 minecraft:pink_petals[flower_amount=2,facing=north]
setblock ~-2 ~0 ~9 minecraft:pink_petals[flower_amount=3,facing=north]
setblock ~-1 ~0 ~9 minecraft:pink_petals[flower_amount=4,facing=north]
setblock ~11 ~0 ~9 minecraft:fern
setblock ~13 ~0 ~9 minecraft:pink_petals[flower_amount=2,facing=north]
setblock ~-3 ~0 ~10 minecraft:short_grass
setblock ~-2 ~0 ~10 minecraft:pink_petals[flower_amount=4,facing=north]
setblock ~11 ~0 ~10 minecraft:flowering_azalea
setblock ~-2 ~0 ~11 minecraft:flowering_azalea
setblock ~-1 ~0 ~11 minecraft:lily_of_the_valley
setblock ~0 ~0 ~11 minecraft:short_grass
setblock ~1 ~0 ~11 minecraft:azure_bluet
setblock ~2 ~0 ~11 minecraft:flowering_azalea
setblock ~3 ~0 ~11 minecraft:short_grass
setblock ~4 ~0 ~11 minecraft:pink_tulip
setblock ~5 ~0 ~11 minecraft:azure_bluet
setblock ~6 ~0 ~11 minecraft:allium
setblock ~7 ~0 ~11 minecraft:pink_petals[flower_amount=2,facing=north]
setblock ~8 ~0 ~11 minecraft:flowering_azalea
setblock ~9 ~0 ~11 minecraft:pink_petals[flower_amount=4,facing=north]
setblock ~10 ~0 ~11 minecraft:pink_petals[flower_amount=1,facing=north]
setblock ~-3 ~0 ~12 minecraft:lily_of_the_valley
setblock ~-2 ~0 ~12 minecraft:allium
setblock ~-1 ~0 ~12 minecraft:flowering_azalea
setblock ~0 ~0 ~12 minecraft:cornflower
setblock ~3 ~0 ~12 minecraft:pink_petals[flower_amount=1,facing=north]
setblock ~4 ~0 ~12 minecraft:pink_tulip
setblock ~5 ~0 ~12 minecraft:pink_tulip
setblock ~6 ~0 ~12 minecraft:pink_petals[flower_amount=2,facing=north]
setblock ~7 ~0 ~12 minecraft:pink_petals[flower_amount=1,facing=north]
setblock ~8 ~0 ~12 minecraft:pink_petals[flower_amount=4,facing=north]
setblock ~10 ~0 ~12 minecraft:flowering_azalea
setblock ~12 ~0 ~12 minecraft:fern
setblock ~13 ~0 ~12 minecraft:lily_of_the_valley
setblock ~-1 ~0 ~13 minecraft:pink_petals[flower_amount=4,facing=north]
setblock ~3 ~0 ~13 minecraft:pink_petals[flower_amount=4,facing=north]
setblock ~4 ~0 ~13 minecraft:flowering_azalea
setblock ~5 ~0 ~13 minecraft:fern
setblock ~7 ~0 ~13 minecraft:lily_of_the_valley
setblock ~8 ~0 ~13 minecraft:fern
setblock ~9 ~0 ~13 minecraft:pink_petals[flower_amount=2,facing=north]
setblock ~10 ~0 ~13 minecraft:pink_petals[flower_amount=3,facing=north]
setblock ~11 ~0 ~13 minecraft:cornflower
setblock ~12 ~0 ~13 minecraft:flowering_azalea
setblock ~13 ~0 ~13 minecraft:pink_petals[flower_amount=2,facing=north]
setblock ~5 ~1 ~0 minecraft:cherry_door[facing=north,half=lower,hinge=left,open=false]
setblock ~4 ~1 ~4 minecraft:pink_petals[flower_amount=4,facing=north]
setblock ~5 ~1 ~4 minecraft:pink_petals[flower_amount=2,facing=north]
setblock ~6 ~1 ~4 minecraft:pink_petals[flower_amount=3,facing=north]
setblock ~4 ~1 ~5 minecraft:pink_petals[flower_amount=2,facing=north]
setblock ~6 ~1 ~5 minecraft:pink_petals[flower_amount=3,facing=north]
setblock ~4 ~1 ~6 minecraft:pink_petals[flower_amount=3,facing=north]
setblock ~5 ~1 ~6 minecraft:pink_petals[flower_amount=4,facing=north]
setblock ~6 ~1 ~6 minecraft:pink_petals[flower_amount=4,facing=north]
setblock ~3 ~2 ~-3 minecraft:lantern[hanging=false]
setblock ~7 ~2 ~-3 minecraft:lantern[hanging=false]
setblock ~5 ~2 ~0 minecraft:cherry_door[facing=north,half=upper,hinge=left,open=false]
setblock ~9 ~2 ~5 minecraft:cherry_pressure_plate
setblock ~5 ~3 ~-1 minecraft:lantern[hanging=true]
setblock ~2 ~3 ~2 minecraft:lantern[hanging=true]
setblock ~2 ~3 ~8 minecraft:lantern[hanging=true]
setblock ~1 ~5 ~2 minecraft:pink_bed[facing=west,part=head]
setblock ~2 ~5 ~2 minecraft:pink_bed[facing=west,part=foot]
setblock ~2 ~5 ~4 minecraft:pink_carpet
setblock ~2 ~5 ~5 minecraft:pink_carpet
setblock ~2 ~5 ~6 minecraft:pink_carpet
setblock ~1 ~5 ~8 minecraft:pink_bed[facing=west,part=head]
setblock ~2 ~5 ~8 minecraft:pink_bed[facing=west,part=foot]
setblock ~3 ~6 ~3 minecraft:lantern[hanging=true]
setblock ~7 ~6 ~3 minecraft:lantern[hanging=true]
setblock ~1 ~6 ~5 minecraft:lantern[hanging=false]
setblock ~3 ~6 ~7 minecraft:lantern[hanging=true]
setblock ~7 ~6 ~7 minecraft:lantern[hanging=true]
